[2022-11-08 01:48:13,247] WARNING [django.request.log_response:241] Not Found: /service/
[2022-11-08 01:48:19,023] WARNING [django.request.log_response:241] Not Found: /service/
[2022-11-08 02:27:45,614] WARNING [django.request.log_response:241] Forbidden: /doctor/5/services/
[2022-11-08 02:28:08,025] ERROR [django.request.log_response:241] Internal Server Error: /doctor/5/services/
[2022-11-08 02:31:12,337] ERROR [django.request.log_response:241] Internal Server Error: /doctor/5/services/
[2022-11-08 02:32:08,869] ERROR [django.request.log_response:241] Internal Server Error: /doctor/5/services/
[2022-11-08 02:35:11,387] WARNING [django.request.log_response:241] Bad Request: /doctor/5/services/
[2022-11-08 02:44:26,372] ERROR [django.request.log_response:241] Internal Server Error: /doctor/5/services/
[2022-11-08 02:45:37,687] WARNING [django.request.log_response:241] Bad Request: /doctor/5/services/
[2022-11-08 02:47:41,355] WARNING [django.request.log_response:241] Bad Request: /doctor/5/services/
[2022-11-08 02:48:22,871] ERROR [django.request.log_response:241] Internal Server Error: /doctor/5/services/
[2022-11-08 02:55:24,799] ERROR [django.request.log_response:241] Internal Server Error: /doctor/5/services/
Traceback (most recent call last):
  File "/usr/local/lib/python3.10/site-packages/django/core/handlers/exception.py", line 55, in inner
    response = get_response(request)
  File "/usr/local/lib/python3.10/site-packages/django/core/handlers/base.py", line 220, in _get_response
    response = response.render()
  File "/usr/local/lib/python3.10/site-packages/django/template/response.py", line 114, in render
    self.content = self.rendered_content
  File "/usr/local/lib/python3.10/site-packages/rest_framework/response.py", line 70, in rendered_content
    ret = renderer.render(self.data, accepted_media_type, context)
  File "/usr/local/lib/python3.10/site-packages/rest_framework/renderers.py", line 100, in render
    ret = json.dumps(
  File "/usr/local/lib/python3.10/site-packages/rest_framework/utils/json.py", line 25, in dumps
    return json.dumps(*args, **kwargs)
  File "/usr/local/lib/python3.10/json/__init__.py", line 238, in dumps
    **kw).encode(obj)
  File "/usr/local/lib/python3.10/json/encoder.py", line 199, in encode
    chunks = self.iterencode(o, _one_shot=True)
  File "/usr/local/lib/python3.10/json/encoder.py", line 257, in iterencode
    return _iterencode(o, 0)
  File "/usr/local/lib/python3.10/site-packages/rest_framework/utils/encoders.py", line 67, in default
    return super().default(obj)
  File "/usr/local/lib/python3.10/json/encoder.py", line 179, in default
    raise TypeError(f'Object of type {o.__class__.__name__} '
TypeError: Object of type ListSerializer is not JSON serializable
[2022-11-08 02:55:47,671] WARNING [django.request.log_response:241] Bad Request: /doctor/5/services/
[2022-11-08 02:57:05,357] WARNING [django.request.log_response:241] Bad Request: /doctor/5/services/
[2022-11-08 03:44:11,500] WARNING [django.request.log_response:241] Forbidden: /manager/doctor/register/
[2022-11-08 03:44:24,967] WARNING [django.request.log_response:241] Bad Request: /manager/doctor/register/
[2022-11-08 03:44:35,074] WARNING [django.request.log_response:241] Bad Request: /manager/doctor/register/
[2022-11-08 04:03:24,694] WARNING [django.request.log_response:241] Forbidden: /doctor/5/services/22/
[2022-11-08 04:10:13,996] WARNING [django.request.log_response:241] Forbidden: /doctor/5/services/22/
[2022-11-08 04:10:20,005] ERROR [shared.exception_handler.__handle_http404:112] 
[2022-11-08 04:10:20,007] WARNING [django.request.log_response:241] Not Found: /doctor/5/services/22/
[2022-11-08 04:10:58,483] ERROR [shared.exception_handler.__handle_http404:112] 
[2022-11-08 04:10:58,486] WARNING [django.request.log_response:241] Not Found: /doctor/5/services/22/
[2022-11-08 04:11:40,130] ERROR [shared.exception_handler.__handle_http404:112] 
[2022-11-08 04:11:40,131] WARNING [django.request.log_response:241] Not Found: /doctor/5/services/22/
[2022-11-08 04:12:35,667] ERROR [shared.exception_handler.__handle_http404:112] 
[2022-11-08 04:12:35,679] WARNING [django.request.log_response:241] Not Found: /doctor/5/services/22/
[2022-11-08 04:25:13,245] WARNING [django.request.log_response:241] Forbidden: /doctor/5/services/1/
[2022-11-08 04:25:29,603] WARNING [django.request.log_response:241] Bad Request: /doctor/5/services/1/
[2022-11-08 04:25:43,572] ERROR [django.request.log_response:241] Internal Server Error: /doctor/5/services/1/
[2022-11-08 05:55:10,161] ERROR [shared.exception_handler.__handle_http404:112] 
[2022-11-08 05:55:10,164] WARNING [django.request.log_response:241] Not Found: /doctor/5/services/1/
[2022-11-08 05:57:49,405] ERROR [shared.exception_handler.__handle_http404:112] 
[2022-11-08 05:57:49,407] WARNING [django.request.log_response:241] Not Found: /doctor/5/services/3/
[2022-11-08 05:57:59,310] WARNING [django.request.log_response:241] Bad Request: /doctor/5/services/
[2022-11-08 06:24:43,486] WARNING [django.request.log_response:241] Bad Request: /doctor/5/services/
[2022-11-08 06:26:56,223] WARNING [django.request.log_response:241] Bad Request: /doctor/5/services/
[2022-11-08 06:37:05,066] WARNING [django.request.log_response:241] Bad Request: /doctor/5/services/
[2022-11-08 06:37:14,135] WARNING [django.request.log_response:241] Bad Request: /doctor/5/services/
[2022-11-08 06:42:41,551] ERROR [django.request.log_response:241] Internal Server Error: /doctor/5/services/
Traceback (most recent call last):
  File "/usr/local/lib/python3.10/site-packages/django/core/handlers/exception.py", line 55, in inner
    response = get_response(request)
  File "/usr/local/lib/python3.10/site-packages/django/core/handlers/base.py", line 197, in _get_response
    response = wrapped_callback(request, *callback_args, **callback_kwargs)
  File "/usr/local/lib/python3.10/site-packages/django/views/decorators/csrf.py", line 54, in wrapped_view
    return view_func(*args, **kwargs)
  File "/usr/local/lib/python3.10/site-packages/django/views/generic/base.py", line 103, in view
    return self.dispatch(request, *args, **kwargs)
  File "/usr/local/lib/python3.10/site-packages/rest_framework/views.py", line 511, in dispatch
    self.response = self.finalize_response(request, response, *args, **kwargs)
  File "/usr/local/lib/python3.10/site-packages/rest_framework/views.py", line 423, in finalize_response
    assert isinstance(response, HttpResponseBase), (
AssertionError: Expected a `Response`, `HttpResponse` or `HttpStreamingResponse` to be returned from the view, but received a `<class 'NoneType'>`
[2022-11-08 06:46:16,241] ERROR [django.request.log_response:241] Internal Server Error: /doctor/5/services/
[2022-11-08 06:59:05,277] WARNING [django.request.log_response:241] Bad Request: /doctor/5/services/
[2022-11-08 07:04:38,826] WARNING [django.request.log_response:241] Bad Request: /doctor/5/services/
[2022-11-08 07:21:21,816] WARNING [django.request.log_response:241] Bad Request: /doctor/5/services/
