[2022-10-02 04:43:29,606] WARNING [django.request.log_response:241] Unauthorized: /api/suggest/doctor/5/
[2022-10-02 05:03:44,689] WARNING [django.request.log_response:241] Not Found: /api/suggest/doctor/54s/
[2022-10-02 05:03:50,286] ERROR [shared.exception_handler.__handle_attribute_error:122] 'NoneType' object has no attribute 'endTime'
[2022-10-02 05:03:50,288] ERROR [django.request.log_response:241] Internal Server Error: /api/suggest/doctor/54/
[2022-10-02 05:03:55,145] ERROR [django.request.log_response:241] Internal Server Error: /api/suggest/doctor/5/
[2022-10-02 05:04:53,891] ERROR [django.request.log_response:241] Internal Server Error: /api/suggest/doctor/5/
[2022-10-02 13:17:40,535] ERROR [django.request.log_response:241] Internal Server Error: /api/suggest/doctor/5/
[2022-10-02 13:19:27,956] ERROR [django.request.log_response:241] Internal Server Error: /api/suggest/doctor/5/
[2022-10-02 13:20:49,489] ERROR [django.request.log_response:241] Internal Server Error: /api/suggest/doctor/5/
[2022-10-02 13:21:27,298] ERROR [django.request.log_response:241] Internal Server Error: /api/suggest/doctor/5/
[2022-10-02 13:26:14,979] ERROR [django.request.log_response:241] Internal Server Error: /api/suggest/doctor/5/
[2022-10-02 13:42:32,087] ERROR [shared.exception_handler.__handle_attribute_error:122] 'GenericRelatedObjectManager' object has no attribute 'delete'
[2022-10-02 13:42:32,089] ERROR [django.request.log_response:241] Internal Server Error: /appointments/102/cancel/
[2022-10-02 13:44:29,197] ERROR [shared.exception_handler.__handle_attribute_error:122] APPOINTMENT_CANCELLED_SUCCEED
[2022-10-02 13:44:29,201] ERROR [django.request.log_response:241] Internal Server Error: /appointments/102/cancel/
[2022-10-02 13:48:14,852] ERROR [shared.exception_handler.__handle_attribute_error:122] APPOINTMENT_CANCELLED_SUCCEED
[2022-10-02 13:48:14,860] ERROR [django.request.log_response:241] Internal Server Error: /appointments/102/cancel/
[2022-10-02 15:13:34,331] ERROR [shared.exception_handler.__handle_attribute_error:122] Cannot find 'ád' on Prescription object, 'ád' is an invalid parameter to prefetch_related()
[2022-10-02 15:13:34,335] ERROR [django.request.log_response:241] Internal Server Error: /cicd/
[2022-10-02 10:44:16,786] ERROR [django.request.log_response:241] Internal Server Error: /prescription/
[2022-10-02 10:44:44,814] ERROR [django.request.log_response:241] Internal Server Error: /prescription/
[2022-10-02 10:45:04,152] ERROR [django.request.log_response:241] Internal Server Error: /prescription/
[2022-10-02 10:45:41,342] ERROR [shared.exception_handler.__handle_attribute_error:122] Got AttributeError when attempting to get a value for field `usage` on serializer `PrescriptionDetailSerializer`.
The serializer field might be named incorrectly and not match any attribute or key on the `QuerySet` instance.
Original exception text was: 'QuerySet' object has no attribute 'usage'.
[2022-10-02 10:45:41,347] ERROR [django.request.log_response:241] Internal Server Error: /prescription/
[2022-10-02 10:47:31,755] ERROR [django.request.log_response:241] Internal Server Error: /prescription/
[2022-10-02 10:49:49,131] ERROR [django.request.log_response:241] Internal Server Error: /prescription/
[2022-10-02 10:50:17,775] ERROR [django.request.log_response:241] Internal Server Error: /prescription/
[2022-10-02 10:52:24,827] ERROR [django.request.log_response:241] Internal Server Error: /prescription/
[2022-10-02 10:56:41,020] ERROR [shared.exception_handler.__handle_attribute_error:122] 'NoneType' object has no attribute 'save'
[2022-10-02 10:56:41,023] ERROR [django.request.log_response:241] Internal Server Error: /prescription/
[2022-10-02 10:57:56,611] ERROR [shared.exception_handler.__handle_attribute_error:122] Got AttributeError when attempting to get a value for field `guide` on serializer `PrescriptionDetailSerializer`.
The serializer field might be named incorrectly and not match any attribute or key on the `QuerySet` instance.
Original exception text was: 'QuerySet' object has no attribute 'guide'.
[2022-10-02 10:57:56,616] ERROR [django.request.log_response:241] Internal Server Error: /prescription/
[2022-10-02 11:07:26,328] ERROR [django.request.log_response:241] Internal Server Error: /prescription/
[2022-10-02 11:12:20,697] ERROR [django.request.log_response:241] Internal Server Error: /prescription/
Traceback (most recent call last):
  File "E:\Enviroment\python\version3\lib\site-packages\django\core\handlers\exception.py", line 55, in inner
    response = get_response(request)
  File "E:\Enviroment\python\version3\lib\site-packages\django\core\handlers\base.py", line 220, in _get_response
    response = response.render()
  File "E:\Enviroment\python\version3\lib\site-packages\django\template\response.py", line 114, in render
    self.content = self.rendered_content
  File "E:\Enviroment\python\version3\lib\site-packages\rest_framework\response.py", line 70, in rendered_content
    ret = renderer.render(self.data, accepted_media_type, context)
  File "E:\Enviroment\python\version3\lib\site-packages\rest_framework\renderers.py", line 100, in render
    ret = json.dumps(
  File "E:\Enviroment\python\version3\lib\site-packages\rest_framework\utils\json.py", line 25, in dumps
    return json.dumps(*args, **kwargs)
  File "E:\Enviroment\python\version3\lib\json\__init__.py", line 238, in dumps
    **kw).encode(obj)
  File "E:\Enviroment\python\version3\lib\json\encoder.py", line 199, in encode
    chunks = self.iterencode(o, _one_shot=True)
  File "E:\Enviroment\python\version3\lib\json\encoder.py", line 257, in iterencode
    return _iterencode(o, 0)
  File "E:\Enviroment\python\version3\lib\site-packages\rest_framework\utils\encoders.py", line 67, in default
    return super().default(obj)
  File "E:\Enviroment\python\version3\lib\json\encoder.py", line 179, in default
    raise TypeError(f'Object of type {o.__class__.__name__} '
TypeError: Object of type PrescriptionDetail is not JSON serializable
[2022-10-02 11:14:41,566] ERROR [django.request.log_response:241] Internal Server Error: /prescription/
[2022-10-02 11:17:41,008] ERROR [django.request.log_response:241] Internal Server Error: /prescription/
[2022-10-02 11:19:55,337] ERROR [django.request.log_response:241] Internal Server Error: /prescription/
[2022-10-02 11:23:12,006] ERROR [django.request.log_response:241] Internal Server Error: /prescription/
[2022-10-02 11:23:43,796] ERROR [django.request.log_response:241] Internal Server Error: /prescription/
[2022-10-02 11:39:37,594] ERROR [django.request.log_response:241] Internal Server Error: /prescription/
[2022-10-02 11:41:31,113] ERROR [django.request.log_response:241] Internal Server Error: /prescription/
[2022-10-02 11:42:00,715] ERROR [django.request.log_response:241] Internal Server Error: /prescription/
[2022-10-02 11:43:24,644] ERROR [django.request.log_response:241] Internal Server Error: /prescription/
[2022-10-02 12:00:59,794] ERROR [django.request.log_response:241] Internal Server Error: /prescription/
[2022-10-02 12:02:10,043] ERROR [django.request.log_response:241] Internal Server Error: /prescription/
[2022-10-02 12:03:48,715] ERROR [django.request.log_response:241] Internal Server Error: /prescription/
[2022-10-02 12:04:18,666] ERROR [django.request.log_response:241] Internal Server Error: /prescription/
[2022-10-02 18:33:22,555] WARNING [django.request.log_response:241] Not Found: /prescription/1/
[2022-10-02 18:35:27,264] WARNING [django.request.log_response:241] Not Found: /prescription/1/
[2022-10-02 18:36:34,334] WARNING [django.request.log_response:241] Not Found: /prescription/doctor/1/
[2022-10-02 18:37:54,574] WARNING [django.request.log_response:241] Not Found: /prescription/doctor/:healthRecord/
[2022-10-02 18:38:22,286] WARNING [django.request.log_response:241] Not Found: /prescription/doctor/:healthRecord/
[2022-10-02 18:38:39,459] WARNING [django.request.log_response:241] Not Found: /prescription/doctor/:healthRecord
[2022-10-02 18:39:15,279] WARNING [django.request.log_response:241] Forbidden: /prescription/doctor/1/
[2022-10-02 18:39:38,934] ERROR [shared.exception_handler.__handle_attribute_error:122] Cannot find 'prescription_details' on Prescription object, 'prescription_details' is an invalid parameter to prefetch_related()
[2022-10-02 18:39:38,936] ERROR [django.request.log_response:241] Internal Server Error: /prescription/doctor/1/
[2022-10-02 20:49:51,653] ERROR [shared.exception_handler.__handle_attribute_error:122] Cannot find 'prescription_detail_set' on Prescription object, 'prescription_detail_set' is an invalid parameter to prefetch_related()
[2022-10-02 20:49:51,655] ERROR [django.request.log_response:241] Internal Server Error: /prescription/doctor/1/
[2022-10-02 20:50:34,077] ERROR [shared.exception_handler.__handle_attribute_error:122] Cannot find 'prescription_detail_set' on Prescription object, 'prescription_detail_set' is an invalid parameter to prefetch_related()
[2022-10-02 20:50:34,079] ERROR [django.request.log_response:241] Internal Server Error: /prescription/doctor/1/
[2022-10-02 21:00:14,847] ERROR [shared.exception_handler.__handle_attribute_error:122] Cannot find 'prescription_detail_set' on Prescription object, 'prescription_detail_set' is an invalid parameter to prefetch_related()
[2022-10-02 21:00:14,849] ERROR [django.request.log_response:241] Internal Server Error: /prescription/doctor/1/
[2022-10-02 22:04:04,941] ERROR [shared.exception_handler.__handle_attribute_error:122] Cannot find 'prescriptiondetail_set ' on Prescription object, 'prescriptiondetail_set ' is an invalid parameter to prefetch_related()
[2022-10-02 22:04:04,944] ERROR [django.request.log_response:241] Internal Server Error: /prescription/doctor/1/
[2022-10-02 22:26:05,997] ERROR [shared.exception_handler.__handle_attribute_error:122] Cannot find 'prescriptiondetail_set ' on Prescription object, 'prescriptiondetail_set ' is an invalid parameter to prefetch_related()
[2022-10-02 22:26:06,000] ERROR [django.request.log_response:241] Internal Server Error: /prescription/doctor/1/
[2022-10-02 22:45:30,359] ERROR [shared.exception_handler.__handle_attribute_error:122] 'dict' object has no attribute 'details'
[2022-10-02 22:45:30,362] ERROR [django.request.log_response:241] Internal Server Error: /prescription/doctor/1/
[2022-10-02 22:50:01,554] ERROR [django.request.log_response:241] Internal Server Error: /prescription/doctor/1/
[2022-10-02 22:55:05,930] ERROR [django.request.log_response:241] Internal Server Error: /prescription/doctor/1/
[2022-10-02 23:08:49,600] ERROR [django.request.log_response:241] Internal Server Error: /prescription/doctor/1/
[2022-10-02 23:09:15,294] ERROR [django.request.log_response:241] Internal Server Error: /prescription/doctor/1/
[2022-10-02 23:09:33,789] ERROR [django.request.log_response:241] Internal Server Error: /prescription/doctor/1/
Traceback (most recent call last):
  File "E:\Enviroment\python\version3\lib\site-packages\rest_framework\views.py", line 506, in dispatch
    response = handler(request, *args, **kwargs)
  File "E:\Enviroment\python\version3\lib\site-packages\rest_framework\generics.py", line 208, in get
    return self.retrieve(request, *args, **kwargs)
  File "E:\Document\capstone\service.cms\service.cms\app\prescription\views.py", line 45, in retrieve
    prescriptions = PrescriptionDetail.objects.select_related('prescription').filter(prescription__healthRecord__startedAt ='')
  File "E:\Enviroment\python\version3\lib\site-packages\django\db\models\query.py", line 1071, in filter
    return self._filter_or_exclude(False, args, kwargs)
  File "E:\Enviroment\python\version3\lib\site-packages\django\db\models\query.py", line 1089, in _filter_or_exclude
    clone._filter_or_exclude_inplace(negate, args, kwargs)
  File "E:\Enviroment\python\version3\lib\site-packages\django\db\models\query.py", line 1096, in _filter_or_exclude_inplace
    self._query.add_q(Q(*args, **kwargs))
  File "E:\Enviroment\python\version3\lib\site-packages\django\db\models\sql\query.py", line 1502, in add_q
    clause, _ = self._add_q(q_object, self.used_aliases)
  File "E:\Enviroment\python\version3\lib\site-packages\django\db\models\sql\query.py", line 1532, in _add_q
    child_clause, needed_inner = self.build_filter(
  File "E:\Enviroment\python\version3\lib\site-packages\django\db\models\sql\query.py", line 1448, in build_filter
    condition = self.build_lookup(lookups, col, value)
  File "E:\Enviroment\python\version3\lib\site-packages\django\db\models\sql\query.py", line 1273, in build_lookup
    lookup = lookup_class(lhs, rhs)
  File "E:\Enviroment\python\version3\lib\site-packages\django\db\models\lookups.py", line 27, in __init__
    self.rhs = self.get_prep_lookup()
  File "E:\Enviroment\python\version3\lib\site-packages\django\db\models\lookups.py", line 85, in get_prep_lookup
    return self.lhs.output_field.get_prep_value(self.rhs)
  File "E:\Enviroment\python\version3\lib\site-packages\django\db\models\fields\__init__.py", line 1403, in get_prep_value
    return self.to_python(value)
  File "E:\Enviroment\python\version3\lib\site-packages\django\db\models\fields\__init__.py", line 1369, in to_python
    raise exceptions.ValidationError(
django.core.exceptions.ValidationError: ['�� value has an invalid date format. It must be in YYYY-MM-DD format.']

During handling of the above exception, another exception occurred:

Traceback (most recent call last):
  File "E:\Enviroment\python\version3\lib\site-packages\django\core\handlers\exception.py", line 55, in inner
    response = get_response(request)
  File "E:\Enviroment\python\version3\lib\site-packages\django\core\handlers\base.py", line 197, in _get_response
    response = wrapped_callback(request, *callback_args, **callback_kwargs)
  File "E:\Enviroment\python\version3\lib\site-packages\django\views\decorators\csrf.py", line 54, in wrapped_view
    return view_func(*args, **kwargs)
  File "E:\Enviroment\python\version3\lib\site-packages\django\views\generic\base.py", line 84, in view
    return self.dispatch(request, *args, **kwargs)
  File "E:\Enviroment\python\version3\lib\site-packages\rest_framework\views.py", line 509, in dispatch
    response = self.handle_exception(exc)
  File "E:\Enviroment\python\version3\lib\site-packages\rest_framework\views.py", line 466, in handle_exception
    response = exception_handler(exc, context)
  File "E:\Document\capstone\service.cms\service.cms\app\shared\exception_handler.py", line 179, in custom_exception_handler
    return cached_exceptions[exception_name](exc, context)
  File "E:\Document\capstone\service.cms\service.cms\app\shared\exception_handler.py", line 35, in __handle_validation_error
    data = exc.detail
AttributeError: 'ValidationError' object has no attribute 'detail'
[2022-10-02 23:16:01,290] ERROR [shared.exception_handler.__handle_attribute_error:122] 'NoneType' object has no attribute 'append'
[2022-10-02 23:16:01,294] ERROR [django.request.log_response:241] Internal Server Error: /prescription/doctor/1/
[2022-10-02 23:16:42,885] ERROR [shared.exception_handler.__handle_attribute_error:122] 'NoneType' object has no attribute 'append'
[2022-10-02 23:16:42,887] ERROR [django.request.log_response:241] Internal Server Error: /prescription/doctor/1/
[2022-10-02 23:17:23,469] ERROR [shared.exception_handler.__handle_attribute_error:122] 'NoneType' object has no attribute 'append'
[2022-10-02 23:17:23,472] ERROR [django.request.log_response:241] Internal Server Error: /prescription/doctor/1/
[2022-10-02 23:18:18,758] ERROR [django.request.log_response:241] Internal Server Error: /prescription/doctor/1/
Traceback (most recent call last):
  File "E:\Enviroment\python\version3\lib\site-packages\django\core\handlers\exception.py", line 55, in inner
    response = get_response(request)
  File "E:\Enviroment\python\version3\lib\site-packages\django\core\handlers\base.py", line 220, in _get_response
    response = response.render()
  File "E:\Enviroment\python\version3\lib\site-packages\django\template\response.py", line 114, in render
    self.content = self.rendered_content
  File "E:\Enviroment\python\version3\lib\site-packages\rest_framework\response.py", line 70, in rendered_content
    ret = renderer.render(self.data, accepted_media_type, context)
  File "E:\Enviroment\python\version3\lib\site-packages\rest_framework\renderers.py", line 100, in render
    ret = json.dumps(
  File "E:\Enviroment\python\version3\lib\site-packages\rest_framework\utils\json.py", line 25, in dumps
    return json.dumps(*args, **kwargs)
  File "E:\Enviroment\python\version3\lib\json\__init__.py", line 238, in dumps
    **kw).encode(obj)
  File "E:\Enviroment\python\version3\lib\json\encoder.py", line 199, in encode
    chunks = self.iterencode(o, _one_shot=True)
  File "E:\Enviroment\python\version3\lib\json\encoder.py", line 257, in iterencode
    return _iterencode(o, 0)
  File "E:\Enviroment\python\version3\lib\site-packages\rest_framework\utils\encoders.py", line 67, in default
    return super().default(obj)
  File "E:\Enviroment\python\version3\lib\json\encoder.py", line 179, in default
    raise TypeError(f'Object of type {o.__class__.__name__} '
TypeError: Object of type Prescription is not JSON serializable
[2022-10-02 23:24:21,689] ERROR [django.request.log_response:241] Internal Server Error: /prescription/doctor/52/
Traceback (most recent call last):
  File "E:\Enviroment\python\version3\lib\site-packages\django\core\handlers\exception.py", line 55, in inner
    response = get_response(request)
  File "E:\Enviroment\python\version3\lib\site-packages\django\core\handlers\base.py", line 220, in _get_response
    response = response.render()
  File "E:\Enviroment\python\version3\lib\site-packages\django\template\response.py", line 114, in render
    self.content = self.rendered_content
  File "E:\Enviroment\python\version3\lib\site-packages\rest_framework\response.py", line 70, in rendered_content
    ret = renderer.render(self.data, accepted_media_type, context)
  File "E:\Enviroment\python\version3\lib\site-packages\rest_framework\renderers.py", line 100, in render
    ret = json.dumps(
  File "E:\Enviroment\python\version3\lib\site-packages\rest_framework\utils\json.py", line 25, in dumps
    return json.dumps(*args, **kwargs)
  File "E:\Enviroment\python\version3\lib\json\__init__.py", line 238, in dumps
    **kw).encode(obj)
  File "E:\Enviroment\python\version3\lib\json\encoder.py", line 199, in encode
    chunks = self.iterencode(o, _one_shot=True)
  File "E:\Enviroment\python\version3\lib\json\encoder.py", line 257, in iterencode
    return _iterencode(o, 0)
  File "E:\Enviroment\python\version3\lib\site-packages\rest_framework\utils\encoders.py", line 67, in default
    return super().default(obj)
  File "E:\Enviroment\python\version3\lib\json\encoder.py", line 179, in default
    raise TypeError(f'Object of type {o.__class__.__name__} '
TypeError: Object of type ListSerializer is not JSON serializable
