[2022-10-07 10:26:09,420] WARNING [django.request.log_response:241] Unauthorized: /doctor/health-records/1/
[2022-10-07 10:26:20,483] ERROR [django.request.log_response:241] Internal Server Error: /doctor/health-records/1/
[2022-10-07 10:44:18,984] ERROR [django.request.log_response:241] Internal Server Error: /doctor/health-records/1/
[2022-10-07 10:47:00,564] ERROR [django.request.log_response:241] Internal Server Error: /doctor/health-records/1/
[2022-10-07 10:49:15,459] ERROR [django.request.log_response:241] Internal Server Error: /doctor/health-records/1/
[2022-10-07 11:06:43,181] ERROR [shared.exception_handler.__handle_attribute_error:122] 'HealthRecord' object has no attribute 'patientmedicalhistory'
[2022-10-07 11:06:43,186] ERROR [django.request.log_response:241] Internal Server Error: /doctor/health-records/1/
[2022-10-07 11:07:25,285] ERROR [shared.exception_handler.__handle_attribute_error:122] 'HealthRecord' object has no attribute 'medical_history'
[2022-10-07 11:07:25,291] ERROR [django.request.log_response:241] Internal Server Error: /doctor/health-records/1/
[2022-10-07 11:07:56,263] ERROR [django.request.log_response:241] Internal Server Error: /doctor/health-records/1/
[2022-10-07 11:10:44,809] ERROR [django.request.log_response:241] Internal Server Error: /doctor/health-records/1/
[2022-10-07 11:11:29,166] ERROR [django.request.log_response:241] Internal Server Error: /doctor/health-records/1/
[2022-10-07 11:12:47,977] ERROR [django.request.log_response:241] Internal Server Error: /doctor/health-records/1/
[2022-10-07 11:13:34,291] ERROR [django.request.log_response:241] Internal Server Error: /doctor/health-records/1/
[2022-10-07 12:23:15,104] WARNING [django.request.log_response:241] Not Found: /supervisor/health-record/1/
[2022-10-07 12:23:34,885] WARNING [django.request.log_response:241] Unauthorized: /supervisor/health-records/1/
[2022-10-07 12:26:13,956] WARNING [django.request.log_response:241] Forbidden: /supervisor/health-records/1/
[2022-10-07 12:26:35,571] WARNING [django.request.log_response:241] Forbidden: /supervisor/health-records/1/
[2022-10-07 12:35:01,805] WARNING [django.request.log_response:241] Forbidden: /supervisor/health-records/1/
[2022-10-07 12:35:47,507] WARNING [django.request.log_response:241] Forbidden: /supervisor/health-records/1/
[2022-10-07 12:40:33,171] ERROR [django.request.log_response:241] Internal Server Error: /supervisor/health-records/1/
[2022-10-07 12:41:23,664] ERROR [django.request.log_response:241] Internal Server Error: /supervisor/health-records/1/
[2022-10-07 12:44:38,277] ERROR [django.request.log_response:241] Internal Server Error: /supervisor/health-records/1/
[2022-10-07 12:45:01,183] ERROR [django.request.log_response:241] Internal Server Error: /supervisor/health-records/1/
[2022-10-07 12:45:27,523] ERROR [django.request.log_response:241] Internal Server Error: /supervisor/health-records/1/
[2022-10-07 12:46:46,391] WARNING [django.request.log_response:241] Bad Request: /supervisor/health-records/1/
[2022-10-07 12:47:19,002] ERROR [django.request.log_response:241] Internal Server Error: /supervisor/health-records/1/
[2022-10-07 12:54:17,961] ERROR [django.request.log_response:241] Internal Server Error: /supervisor/health-records/1/
[2022-10-07 12:54:47,940] ERROR [django.request.log_response:241] Internal Server Error: /supervisor/health-records/1/
[2022-10-07 13:02:50,969] ERROR [django.request.log_response:241] Internal Server Error: /supervisor/health-records/1/
[2022-10-07 13:09:19,125] ERROR [django.request.log_response:241] Internal Server Error: /supervisor/health-records/1/
[2022-10-07 13:13:59,186] ERROR [django.request.log_response:241] Internal Server Error: /supervisor/health-records/1/
[2022-10-07 13:15:34,706] ERROR [django.request.log_response:241] Internal Server Error: /supervisor/health-records/1/
[2022-10-07 13:17:03,442] ERROR [django.request.log_response:241] Internal Server Error: /supervisor/health-records/1/
[2022-10-07 05:53:55,453] WARNING [django.request.log_response:241] Unauthorized: /doctors/nearest/
[2022-10-07 05:59:10,893] WARNING [django.request.log_response:241] Not Found: /favicon.ico
[2022-10-07 06:18:49,518] WARNING [django.request.log_response:241] Forbidden: /doctor/5/packages/
[2022-10-07 06:19:08,296] WARNING [django.request.log_response:241] Bad Request: /doctor/5/packages/
[2022-10-07 06:19:18,612] WARNING [django.request.log_response:241] Bad Request: /doctor/5/packages/
[2022-10-07 06:44:53,652] ERROR [shared.exception_handler.__handle_attribute_error:122] 'DoctorSpecialist' object has no attribute 'name'
[2022-10-07 06:44:53,660] ERROR [django.request.log_response:241] Internal Server Error: /doctor/5/
[2022-10-07 06:49:49,345] ERROR [shared.exception_handler.__handle_attribute_error:122] 'DoctorSpecialist' object has no attribute 'name'
[2022-10-07 06:49:49,351] ERROR [django.request.log_response:241] Internal Server Error: /doctor/5/
[2022-10-07 07:44:28,652] ERROR [django.request.log_response:241] Internal Server Error: /api/specialists/doctors/
Traceback (most recent call last):
  File "/usr/local/lib/python3.10/site-packages/django/core/handlers/exception.py", line 55, in inner
    response = get_response(request)
  File "/usr/local/lib/python3.10/site-packages/django/core/handlers/base.py", line 197, in _get_response
    response = wrapped_callback(request, *callback_args, **callback_kwargs)
  File "/usr/local/lib/python3.10/site-packages/django/views/decorators/csrf.py", line 54, in wrapped_view
    return view_func(*args, **kwargs)
  File "/usr/local/lib/python3.10/site-packages/django/views/generic/base.py", line 84, in view
    return self.dispatch(request, *args, **kwargs)
  File "/usr/local/lib/python3.10/site-packages/rest_framework/views.py", line 511, in dispatch
    self.response = self.finalize_response(request, response, *args, **kwargs)
  File "/usr/local/lib/python3.10/site-packages/rest_framework/views.py", line 423, in finalize_response
    assert isinstance(response, HttpResponseBase), (
AssertionError: Expected a `Response`, `HttpResponse` or `HttpStreamingResponse` to be returned from the view, but received a `<class 'coroutine'>`
[2022-10-07 07:55:30,757] ERROR [django.request.log_response:241] Internal Server Error: /health-records/1/
[2022-10-07 08:02:33,968] ERROR [django.request.log_response:241] Internal Server Error: /api/specialists/doctors/
Traceback (most recent call last):
  File "/usr/local/lib/python3.10/site-packages/django/core/handlers/exception.py", line 55, in inner
    response = get_response(request)
  File "/usr/local/lib/python3.10/site-packages/django/core/handlers/base.py", line 197, in _get_response
    response = wrapped_callback(request, *callback_args, **callback_kwargs)
  File "/usr/local/lib/python3.10/site-packages/django/views/decorators/csrf.py", line 54, in wrapped_view
    return view_func(*args, **kwargs)
  File "/usr/local/lib/python3.10/site-packages/django/views/generic/base.py", line 84, in view
    return self.dispatch(request, *args, **kwargs)
  File "/usr/local/lib/python3.10/site-packages/rest_framework/views.py", line 511, in dispatch
    self.response = self.finalize_response(request, response, *args, **kwargs)
  File "/usr/local/lib/python3.10/site-packages/rest_framework/views.py", line 423, in finalize_response
    assert isinstance(response, HttpResponseBase), (
AssertionError: Expected a `Response`, `HttpResponse` or `HttpStreamingResponse` to be returned from the view, but received a `<class 'coroutine'>`
[2022-10-07 08:03:08,960] ERROR [django.request.log_response:241] Internal Server Error: /api/specialists/doctors/
Traceback (most recent call last):
  File "/usr/local/lib/python3.10/site-packages/django/core/handlers/exception.py", line 55, in inner
    response = get_response(request)
  File "/usr/local/lib/python3.10/site-packages/django/core/handlers/base.py", line 197, in _get_response
    response = wrapped_callback(request, *callback_args, **callback_kwargs)
  File "/usr/local/lib/python3.10/site-packages/asgiref/sync.py", line 218, in __call__
    return call_result.result()
  File "/usr/local/lib/python3.10/concurrent/futures/_base.py", line 451, in result
    return self.__get_result()
  File "/usr/local/lib/python3.10/concurrent/futures/_base.py", line 403, in __get_result
    raise self._exception
  File "/usr/local/lib/python3.10/site-packages/asgiref/sync.py", line 284, in main_wrap
    result = await self.awaitable(*args, **kwargs)
TypeError: object Response can't be used in 'await' expression
[2022-10-07 08:04:04,979] ERROR [django.request.log_response:241] Internal Server Error: /api/specialists/doctors/
Traceback (most recent call last):
  File "/usr/local/lib/python3.10/site-packages/django/core/handlers/exception.py", line 55, in inner
    response = get_response(request)
  File "/usr/local/lib/python3.10/site-packages/django/core/handlers/base.py", line 197, in _get_response
    response = wrapped_callback(request, *callback_args, **callback_kwargs)
  File "/usr/local/lib/python3.10/site-packages/asgiref/sync.py", line 218, in __call__
    return call_result.result()
  File "/usr/local/lib/python3.10/concurrent/futures/_base.py", line 451, in result
    return self.__get_result()
  File "/usr/local/lib/python3.10/concurrent/futures/_base.py", line 403, in __get_result
    raise self._exception
  File "/usr/local/lib/python3.10/site-packages/asgiref/sync.py", line 284, in main_wrap
    result = await self.awaitable(*args, **kwargs)
TypeError: object Response can't be used in 'await' expression
[2022-10-07 08:08:24,446] ERROR [django.request.log_response:241] Internal Server Error: /api/specialists/doctors/
[2022-10-07 08:14:02,460] ERROR [django.request.log_response:241] Internal Server Error: /api/specialists/doctors/
[2022-10-07 08:16:21,651] ERROR [django.request.log_response:241] Internal Server Error: /api/specialists/doctors/
Traceback (most recent call last):
  File "/usr/local/lib/python3.10/site-packages/django/core/handlers/exception.py", line 55, in inner
    response = get_response(request)
  File "/usr/local/lib/python3.10/site-packages/django/core/handlers/base.py", line 197, in _get_response
    response = wrapped_callback(request, *callback_args, **callback_kwargs)
  File "/usr/local/lib/python3.10/site-packages/django/views/decorators/csrf.py", line 54, in wrapped_view
    return view_func(*args, **kwargs)
  File "/usr/local/lib/python3.10/site-packages/django/views/generic/base.py", line 84, in view
    return self.dispatch(request, *args, **kwargs)
  File "/usr/local/lib/python3.10/site-packages/rest_framework/views.py", line 511, in dispatch
    self.response = self.finalize_response(request, response, *args, **kwargs)
  File "/usr/local/lib/python3.10/site-packages/rest_framework/views.py", line 423, in finalize_response
    assert isinstance(response, HttpResponseBase), (
AssertionError: Expected a `Response`, `HttpResponse` or `HttpStreamingResponse` to be returned from the view, but received a `<class 'coroutine'>`
[2022-10-07 08:25:21,747] ERROR [django.request.log_response:241] Internal Server Error: /api/specialists/doctors/
Traceback (most recent call last):
  File "/usr/local/lib/python3.10/site-packages/django/core/handlers/exception.py", line 55, in inner
    response = get_response(request)
  File "/usr/local/lib/python3.10/site-packages/django/core/handlers/base.py", line 197, in _get_response
    response = wrapped_callback(request, *callback_args, **callback_kwargs)
  File "/usr/local/lib/python3.10/site-packages/django/views/decorators/csrf.py", line 54, in wrapped_view
    return view_func(*args, **kwargs)
  File "/usr/local/lib/python3.10/site-packages/django/views/generic/base.py", line 84, in view
    return self.dispatch(request, *args, **kwargs)
  File "/usr/local/lib/python3.10/site-packages/rest_framework/views.py", line 511, in dispatch
    self.response = self.finalize_response(request, response, *args, **kwargs)
  File "/usr/local/lib/python3.10/site-packages/rest_framework/views.py", line 423, in finalize_response
    assert isinstance(response, HttpResponseBase), (
AssertionError: Expected a `Response`, `HttpResponse` or `HttpStreamingResponse` to be returned from the view, but received a `<class 'coroutine'>`
[2022-10-07 11:12:21,876] ERROR [django.request.log_response:241] Internal Server Error: /api/specialists/doctors/
[2022-10-07 11:35:40,311] ERROR [shared.exception_handler.__handle_attribute_error:122] 'str' object has no attribute 'items'
[2022-10-07 11:35:40,317] ERROR [django.request.log_response:241] Internal Server Error: /api/specialists/doctors/
[2022-10-07 11:36:42,689] ERROR [django.request.log_response:241] Internal Server Error: /api/specialists/doctors/
[2022-10-07 13:10:08,286] ERROR [django.request.log_response:241] Internal Server Error: /api/specialists/doctors/
[2022-10-07 13:13:29,132] ERROR [shared.exception_handler.__handle_attribute_error:122] 'Specialist' object has no attribute 'doctor_list'
[2022-10-07 13:13:29,145] ERROR [django.request.log_response:241] Internal Server Error: /api/specialists/doctors/
[2022-10-07 13:14:57,256] ERROR [shared.exception_handler.__handle_attribute_error:122] 'Specialist' object has no attribute 'doctor_list'
[2022-10-07 13:14:57,262] ERROR [django.request.log_response:241] Internal Server Error: /api/specialists/doctors/
[2022-10-07 13:14:59,840] ERROR [shared.exception_handler.__handle_attribute_error:122] 'Specialist' object has no attribute 'doctor_list'
[2022-10-07 13:14:59,843] ERROR [django.request.log_response:241] Internal Server Error: /api/specialists/doctors/
[2022-10-07 13:15:42,391] ERROR [shared.exception_handler.__handle_attribute_error:122] 'Specialist' object has no attribute 'doctor_list'
[2022-10-07 13:15:42,398] ERROR [django.request.log_response:241] Internal Server Error: /api/specialists/doctors/
[2022-10-07 13:16:59,826] ERROR [shared.exception_handler.__handle_attribute_error:122] 'Specialist' object has no attribute 'doctor_list'
[2022-10-07 13:16:59,879] ERROR [django.request.log_response:241] Internal Server Error: /api/specialists/doctors/
[2022-10-07 13:34:28,857] WARNING [django.request.log_response:241] Bad Request: /specialists/1/doctors/
[2022-10-07 13:37:42,412] ERROR [shared.exception_handler.__handle_attribute_error:122] 'DoctorSpecialist' object has no attribute 'name'
[2022-10-07 13:37:42,417] ERROR [django.request.log_response:241] Internal Server Error: /specialists/2/doctors/
[2022-10-07 13:54:02,669] ERROR [shared.exception_handler.__handle_attribute_error:122] 'list' object has no attribute 'pk'
[2022-10-07 13:54:02,678] ERROR [django.request.log_response:241] Internal Server Error: /api/specialists/doctors/
[2022-10-07 13:55:19,206] ERROR [shared.exception_handler.__handle_attribute_error:122] 'list' object has no attribute 'pk'
[2022-10-07 13:55:19,218] ERROR [django.request.log_response:241] Internal Server Error: /api/specialists/doctors/
