[2022-09-13 02:55:44,110] WARNING [django.request.log_response:241] Unauthorized: /appointments/25/reschedule/
[2022-09-13 03:04:26,068] ERROR [shared.exception_handler.__handle_http404:112] Appointment matching query does not exist.
[2022-09-13 03:04:26,072] WARNING [django.request.log_response:241] Not Found: /appointments/25/reschedule/
[2022-09-13 03:04:39,935] WARNING [django.request.log_response:241] Bad Request: /appointments/23/reschedule/
[2022-09-13 03:04:52,344] ERROR [shared.exception_handler.__handle_attribute_error:122] 'NoneType' object has no attribute 'pk'
[2022-09-13 03:04:52,345] ERROR [django.request.log_response:241] Internal Server Error: /appointments/23/reschedule/
[2022-09-13 03:05:21,860] ERROR [shared.exception_handler.__handle_attribute_error:122] 'NoneType' object has no attribute 'pk'
[2022-09-13 03:05:21,864] ERROR [django.request.log_response:241] Internal Server Error: /appointments/23/reschedule/
[2022-09-13 03:07:13,462] WARNING [django.request.log_response:241] Bad Request: /appointments/23/reschedule/
[2022-09-13 12:50:33,428] ERROR [django.request.log_response:241] Internal Server Error: /appointments/
[2022-09-13 12:51:13,102] WARNING [django.request.log_response:241] Bad Request: /appointments/
[2022-09-13 12:54:52,947] WARNING [django.request.log_response:241] Bad Request: /appointments/
[2022-09-13 12:55:13,022] WARNING [django.request.log_response:241] Bad Request: /appointments/
[2022-09-13 12:55:18,180] WARNING [django.request.log_response:241] Bad Request: /appointments/
[2022-09-13 12:57:03,319] ERROR [django.request.log_response:241] Internal Server Error: /appointments/
[2022-09-13 12:57:57,986] ERROR [shared.exception_handler.__handle_attribute_error:122] 'PackageMeta' object has no attribute 'duration'
[2022-09-13 12:57:57,990] ERROR [django.request.log_response:241] Internal Server Error: /appointments/
[2022-09-13 13:15:05,632] ERROR [apscheduler.executors.default.run_job:131] Job "perform_check_appointment (trigger: date[2022-09-13 13:15:05 UTC], next run at: 2022-09-13 13:15:05 UTC)" raised an exception
Traceback (most recent call last):
  File "/usr/local/lib/python3.9/site-packages/apscheduler/executors/base.py", line 125, in run_job
    retval = job.func(*job.args, **job.kwargs)
  File "/usr/src/app/appointment/serializers.py", line 42, in perform_check_appointment
    appointment.historical = json.dumps(serializer.data)
  File "/usr/local/lib/python3.9/json/__init__.py", line 231, in dumps
    return _default_encoder.encode(obj)
  File "/usr/local/lib/python3.9/json/encoder.py", line 199, in encode
    chunks = self.iterencode(o, _one_shot=True)
  File "/usr/local/lib/python3.9/json/encoder.py", line 257, in iterencode
    return _iterencode(o, 0)
  File "/usr/local/lib/python3.9/json/encoder.py", line 179, in default
    raise TypeError(f'Object of type {o.__class__.__name__} '
TypeError: Object of type datetime is not JSON serializable
[2022-09-13 13:18:05,910] ERROR [apscheduler.executors.default.run_job:131] Job "perform_check_appointment (trigger: date[2022-09-13 13:18:05 UTC], next run at: 2022-09-13 13:18:05 UTC)" raised an exception
Traceback (most recent call last):
  File "/usr/local/lib/python3.9/site-packages/apscheduler/executors/base.py", line 125, in run_job
    retval = job.func(*job.args, **job.kwargs)
  File "/usr/src/app/appointment/serializers.py", line 43, in perform_check_appointment
    appointment.save()
  File "/usr/local/lib/python3.9/site-packages/django/db/models/base.py", line 806, in save
    self.save_base(
  File "/usr/local/lib/python3.9/site-packages/django/db/models/base.py", line 857, in save_base
    updated = self._save_table(
  File "/usr/local/lib/python3.9/site-packages/django/db/models/base.py", line 970, in _save_table
    updated = self._do_update(
  File "/usr/local/lib/python3.9/site-packages/django/db/models/base.py", line 1034, in _do_update
    return filtered._update(values) > 0
  File "/usr/local/lib/python3.9/site-packages/django/db/models/query.py", line 885, in _update
    return query.get_compiler(self.db).execute_sql(CURSOR)
  File "/usr/local/lib/python3.9/site-packages/django/db/models/sql/compiler.py", line 1783, in execute_sql
    cursor = super().execute_sql(result_type)
  File "/usr/local/lib/python3.9/site-packages/django/db/models/sql/compiler.py", line 1348, in execute_sql
    sql, params = self.as_sql()
  File "/usr/local/lib/python3.9/site-packages/django/db/backends/mysql/compiler.py", line 50, in as_sql
    update_query, update_params = super().as_sql()
  File "/usr/local/lib/python3.9/site-packages/django/db/models/sql/compiler.py", line 1749, in as_sql
    val = field.get_db_prep_save(val, connection=self.connection)
  File "/usr/local/lib/python3.9/site-packages/django/db/models/fields/__init__.py", line 910, in get_db_prep_save
    return self.get_db_prep_value(value, connection=connection, prepared=False)
  File "/usr/local/lib/python3.9/site-packages/django/db/models/fields/__init__.py", line 905, in get_db_prep_value
    value = self.get_prep_value(value)
  File "/usr/local/lib/python3.9/site-packages/django/db/models/fields/json.py", line 96, in get_prep_value
    return json.dumps(value, cls=self.encoder)
  File "/usr/local/lib/python3.9/json/__init__.py", line 231, in dumps
    return _default_encoder.encode(obj)
  File "/usr/local/lib/python3.9/json/encoder.py", line 199, in encode
    chunks = self.iterencode(o, _one_shot=True)
  File "/usr/local/lib/python3.9/json/encoder.py", line 257, in iterencode
    return _iterencode(o, 0)
  File "/usr/local/lib/python3.9/json/encoder.py", line 179, in default
    raise TypeError(f'Object of type {o.__class__.__name__} '
TypeError: Object of type datetime is not JSON serializable
[2022-09-13 13:19:51,601] WARNING [django.request.log_response:241] Bad Request: /appointments/
[2022-09-13 13:23:46,486] ERROR [shared.exception_handler.__handle_attribute_error:122] 'Appointment' object has no attribute 'dob'
[2022-09-13 13:23:46,492] ERROR [django.request.log_response:241] Internal Server Error: /appointments/35/
[2022-09-13 13:25:51,663] ERROR [shared.exception_handler.__handle_attribute_error:122] 'NoneType' object has no attribute 'strftime'
[2022-09-13 13:25:51,667] ERROR [django.request.log_response:241] Internal Server Error: /appointments/35/
