[2022-08-03 04:13:26,934] WARNING [django.request.log_response:241] Bad Request: /doctor/health-records/
[2022-08-03 04:13:48,495] WARNING [django.request.log_response:241] Unauthorized: /login/
[2022-08-03 04:19:53,759] WARNING [django.request.log_response:241] Forbidden: /login/
[2022-08-03 04:20:46,256] WARNING [django.request.log_response:241] Forbidden: /doctor/health-records/
[2022-08-03 04:21:02,440] WARNING [django.request.log_response:241] Forbidden: /login/
[2022-08-03 04:21:19,520] ERROR [django.request.log_response:241] Internal Server Error: /doctor/health-records/
[2022-08-03 04:25:41,410] WARNING [django.request.log_response:241] Bad Request: /doctor/health-records/
[2022-08-03 04:36:33,105] ERROR [django.request.log_response:241] Internal Server Error: /doctor/health-records/
[2022-08-03 04:37:11,455] ERROR [django.request.log_response:241] Internal Server Error: /doctor/health-records/
[2022-08-03 04:39:57,802] ERROR [django.request.log_response:241] Internal Server Error: /doctor/health-records/
[2022-08-03 04:40:56,196] ERROR [django.request.log_response:241] Internal Server Error: /doctor/health-records/
Traceback (most recent call last):
  File "/usr/local/lib/python3.9/site-packages/django/core/handlers/exception.py", line 55, in inner
    response = get_response(request)
  File "/usr/local/lib/python3.9/site-packages/django/core/handlers/base.py", line 197, in _get_response
    response = wrapped_callback(request, *callback_args, **callback_kwargs)
  File "/usr/local/lib/python3.9/site-packages/django/views/decorators/csrf.py", line 54, in wrapped_view
    return view_func(*args, **kwargs)
  File "/usr/local/lib/python3.9/site-packages/django/views/generic/base.py", line 84, in view
    return self.dispatch(request, *args, **kwargs)
  File "/usr/local/lib/python3.9/site-packages/rest_framework/views.py", line 509, in dispatch
    response = self.handle_exception(exc)
  File "/usr/local/lib/python3.9/site-packages/rest_framework/views.py", line 469, in handle_exception
    self.raise_uncaught_exception(exc)
  File "/usr/local/lib/python3.9/site-packages/rest_framework/views.py", line 480, in raise_uncaught_exception
    raise exc
  File "/usr/local/lib/python3.9/site-packages/rest_framework/views.py", line 506, in dispatch
    response = handler(request, *args, **kwargs)
  File "/usr/local/lib/python3.9/site-packages/rest_framework/generics.py", line 190, in post
    return self.create(request, *args, **kwargs)
  File "/usr/src/app/health_record/views.py", line 24, in create
    serializer.save()
  File "/usr/local/lib/python3.9/site-packages/rest_framework/serializers.py", line 212, in save
    self.instance = self.create(validated_data)
  File "/usr/local/lib/python3.9/contextlib.py", line 79, in inner
    return func(*args, **kwds)
  File "/usr/src/app/health_record/serializers.py", line 41, in create
    health_record.symptoms = symptom_list
  File "/usr/local/lib/python3.9/site-packages/django/db/models/fields/related_descriptors.py", line 595, in __set__
    raise TypeError(
TypeError: Direct assignment to the reverse side of a related set is prohibited. Use symptoms.set() instead.
[2022-08-03 04:42:24,960] ERROR [django.request.log_response:241] Internal Server Error: /doctor/health-records/
[2022-08-03 04:44:23,915] ERROR [django.request.log_response:241] Internal Server Error: /doctor/health-records/
[2022-08-03 04:44:38,799] ERROR [django.request.log_response:241] Internal Server Error: /doctor/health-records/
Traceback (most recent call last):
  File "/usr/local/lib/python3.9/site-packages/django/core/handlers/exception.py", line 55, in inner
    response = get_response(request)
  File "/usr/local/lib/python3.9/site-packages/django/core/handlers/base.py", line 220, in _get_response
    response = response.render()
  File "/usr/local/lib/python3.9/site-packages/django/template/response.py", line 114, in render
    self.content = self.rendered_content
  File "/usr/local/lib/python3.9/site-packages/rest_framework/response.py", line 70, in rendered_content
    ret = renderer.render(self.data, accepted_media_type, context)
  File "/usr/local/lib/python3.9/site-packages/rest_framework/renderers.py", line 100, in render
    ret = json.dumps(
  File "/usr/local/lib/python3.9/site-packages/rest_framework/utils/json.py", line 25, in dumps
    return json.dumps(*args, **kwargs)
  File "/usr/local/lib/python3.9/json/__init__.py", line 234, in dumps
    return cls(
  File "/usr/local/lib/python3.9/json/encoder.py", line 199, in encode
    chunks = self.iterencode(o, _one_shot=True)
  File "/usr/local/lib/python3.9/json/encoder.py", line 257, in iterencode
    return _iterencode(o, 0)
  File "/usr/local/lib/python3.9/site-packages/rest_framework/utils/encoders.py", line 67, in default
    return super().default(obj)
  File "/usr/local/lib/python3.9/json/encoder.py", line 179, in default
    raise TypeError(f'Object of type {o.__class__.__name__} '
TypeError: Object of type RelatedManager is not JSON serializable
[2022-08-03 04:46:14,044] ERROR [django.request.log_response:241] Internal Server Error: /doctor/health-records/
Traceback (most recent call last):
  File "/usr/local/lib/python3.9/site-packages/django/core/handlers/exception.py", line 55, in inner
    response = get_response(request)
  File "/usr/local/lib/python3.9/site-packages/django/core/handlers/base.py", line 220, in _get_response
    response = response.render()
  File "/usr/local/lib/python3.9/site-packages/django/template/response.py", line 114, in render
    self.content = self.rendered_content
  File "/usr/local/lib/python3.9/site-packages/rest_framework/response.py", line 70, in rendered_content
    ret = renderer.render(self.data, accepted_media_type, context)
  File "/usr/local/lib/python3.9/site-packages/rest_framework/renderers.py", line 100, in render
    ret = json.dumps(
  File "/usr/local/lib/python3.9/site-packages/rest_framework/utils/json.py", line 25, in dumps
    return json.dumps(*args, **kwargs)
  File "/usr/local/lib/python3.9/json/__init__.py", line 234, in dumps
    return cls(
  File "/usr/local/lib/python3.9/json/encoder.py", line 199, in encode
    chunks = self.iterencode(o, _one_shot=True)
  File "/usr/local/lib/python3.9/json/encoder.py", line 257, in iterencode
    return _iterencode(o, 0)
  File "/usr/local/lib/python3.9/site-packages/rest_framework/utils/encoders.py", line 67, in default
    return super().default(obj)
  File "/usr/local/lib/python3.9/json/encoder.py", line 179, in default
    raise TypeError(f'Object of type {o.__class__.__name__} '
TypeError: Object of type RelatedManager is not JSON serializable
[2022-08-03 04:46:17,483] ERROR [django.request.log_response:241] Internal Server Error: /doctor/health-records/
Traceback (most recent call last):
  File "/usr/local/lib/python3.9/site-packages/django/core/handlers/exception.py", line 55, in inner
    response = get_response(request)
  File "/usr/local/lib/python3.9/site-packages/django/core/handlers/base.py", line 220, in _get_response
    response = response.render()
  File "/usr/local/lib/python3.9/site-packages/django/template/response.py", line 114, in render
    self.content = self.rendered_content
  File "/usr/local/lib/python3.9/site-packages/rest_framework/response.py", line 70, in rendered_content
    ret = renderer.render(self.data, accepted_media_type, context)
  File "/usr/local/lib/python3.9/site-packages/rest_framework/renderers.py", line 100, in render
    ret = json.dumps(
  File "/usr/local/lib/python3.9/site-packages/rest_framework/utils/json.py", line 25, in dumps
    return json.dumps(*args, **kwargs)
  File "/usr/local/lib/python3.9/json/__init__.py", line 234, in dumps
    return cls(
  File "/usr/local/lib/python3.9/json/encoder.py", line 199, in encode
    chunks = self.iterencode(o, _one_shot=True)
  File "/usr/local/lib/python3.9/json/encoder.py", line 257, in iterencode
    return _iterencode(o, 0)
  File "/usr/local/lib/python3.9/site-packages/rest_framework/utils/encoders.py", line 67, in default
    return super().default(obj)
  File "/usr/local/lib/python3.9/json/encoder.py", line 179, in default
    raise TypeError(f'Object of type {o.__class__.__name__} '
TypeError: Object of type RelatedManager is not JSON serializable
[2022-08-03 04:46:44,400] ERROR [django.request.log_response:241] Internal Server Error: /doctor/health-records/
Traceback (most recent call last):
  File "/usr/local/lib/python3.9/site-packages/django/core/handlers/exception.py", line 55, in inner
    response = get_response(request)
  File "/usr/local/lib/python3.9/site-packages/django/core/handlers/base.py", line 220, in _get_response
    response = response.render()
  File "/usr/local/lib/python3.9/site-packages/django/template/response.py", line 114, in render
    self.content = self.rendered_content
  File "/usr/local/lib/python3.9/site-packages/rest_framework/response.py", line 70, in rendered_content
    ret = renderer.render(self.data, accepted_media_type, context)
  File "/usr/local/lib/python3.9/site-packages/rest_framework/renderers.py", line 100, in render
    ret = json.dumps(
  File "/usr/local/lib/python3.9/site-packages/rest_framework/utils/json.py", line 25, in dumps
    return json.dumps(*args, **kwargs)
  File "/usr/local/lib/python3.9/json/__init__.py", line 234, in dumps
    return cls(
  File "/usr/local/lib/python3.9/json/encoder.py", line 199, in encode
    chunks = self.iterencode(o, _one_shot=True)
  File "/usr/local/lib/python3.9/json/encoder.py", line 257, in iterencode
    return _iterencode(o, 0)
  File "/usr/local/lib/python3.9/site-packages/rest_framework/utils/encoders.py", line 67, in default
    return super().default(obj)
  File "/usr/local/lib/python3.9/json/encoder.py", line 179, in default
    raise TypeError(f'Object of type {o.__class__.__name__} '
TypeError: Object of type RelatedManager is not JSON serializable
[2022-08-03 04:47:13,089] ERROR [django.request.log_response:241] Internal Server Error: /doctor/health-records/
Traceback (most recent call last):
  File "/usr/local/lib/python3.9/site-packages/django/core/handlers/exception.py", line 55, in inner
    response = get_response(request)
  File "/usr/local/lib/python3.9/site-packages/django/core/handlers/base.py", line 220, in _get_response
    response = response.render()
  File "/usr/local/lib/python3.9/site-packages/django/template/response.py", line 114, in render
    self.content = self.rendered_content
  File "/usr/local/lib/python3.9/site-packages/rest_framework/response.py", line 70, in rendered_content
    ret = renderer.render(self.data, accepted_media_type, context)
  File "/usr/local/lib/python3.9/site-packages/rest_framework/renderers.py", line 100, in render
    ret = json.dumps(
  File "/usr/local/lib/python3.9/site-packages/rest_framework/utils/json.py", line 25, in dumps
    return json.dumps(*args, **kwargs)
  File "/usr/local/lib/python3.9/json/__init__.py", line 234, in dumps
    return cls(
  File "/usr/local/lib/python3.9/json/encoder.py", line 199, in encode
    chunks = self.iterencode(o, _one_shot=True)
  File "/usr/local/lib/python3.9/json/encoder.py", line 257, in iterencode
    return _iterencode(o, 0)
  File "/usr/local/lib/python3.9/site-packages/rest_framework/utils/encoders.py", line 67, in default
    return super().default(obj)
  File "/usr/local/lib/python3.9/json/encoder.py", line 179, in default
    raise TypeError(f'Object of type {o.__class__.__name__} '
TypeError: Object of type RelatedManager is not JSON serializable
[2022-08-03 04:50:02,645] ERROR [django.request.log_response:241] Internal Server Error: /doctor/health-records/
Traceback (most recent call last):
  File "/usr/local/lib/python3.9/site-packages/django/core/handlers/exception.py", line 55, in inner
    response = get_response(request)
  File "/usr/local/lib/python3.9/site-packages/django/core/handlers/base.py", line 220, in _get_response
    response = response.render()
  File "/usr/local/lib/python3.9/site-packages/django/template/response.py", line 114, in render
    self.content = self.rendered_content
  File "/usr/local/lib/python3.9/site-packages/rest_framework/response.py", line 70, in rendered_content
    ret = renderer.render(self.data, accepted_media_type, context)
  File "/usr/local/lib/python3.9/site-packages/rest_framework/renderers.py", line 100, in render
    ret = json.dumps(
  File "/usr/local/lib/python3.9/site-packages/rest_framework/utils/json.py", line 25, in dumps
    return json.dumps(*args, **kwargs)
  File "/usr/local/lib/python3.9/json/__init__.py", line 234, in dumps
    return cls(
  File "/usr/local/lib/python3.9/json/encoder.py", line 199, in encode
    chunks = self.iterencode(o, _one_shot=True)
  File "/usr/local/lib/python3.9/json/encoder.py", line 257, in iterencode
    return _iterencode(o, 0)
  File "/usr/local/lib/python3.9/site-packages/rest_framework/utils/encoders.py", line 67, in default
    return super().default(obj)
  File "/usr/local/lib/python3.9/json/encoder.py", line 179, in default
    raise TypeError(f'Object of type {o.__class__.__name__} '
TypeError: Object of type RelatedManager is not JSON serializable
[2022-08-03 04:51:07,626] ERROR [django.request.log_response:241] Internal Server Error: /doctor/health-records/
Traceback (most recent call last):
  File "/usr/local/lib/python3.9/site-packages/django/core/handlers/exception.py", line 55, in inner
    response = get_response(request)
  File "/usr/local/lib/python3.9/site-packages/django/core/handlers/base.py", line 220, in _get_response
    response = response.render()
  File "/usr/local/lib/python3.9/site-packages/django/template/response.py", line 114, in render
    self.content = self.rendered_content
  File "/usr/local/lib/python3.9/site-packages/rest_framework/response.py", line 70, in rendered_content
    ret = renderer.render(self.data, accepted_media_type, context)
  File "/usr/local/lib/python3.9/site-packages/rest_framework/renderers.py", line 100, in render
    ret = json.dumps(
  File "/usr/local/lib/python3.9/site-packages/rest_framework/utils/json.py", line 25, in dumps
    return json.dumps(*args, **kwargs)
  File "/usr/local/lib/python3.9/json/__init__.py", line 234, in dumps
    return cls(
  File "/usr/local/lib/python3.9/json/encoder.py", line 199, in encode
    chunks = self.iterencode(o, _one_shot=True)
  File "/usr/local/lib/python3.9/json/encoder.py", line 257, in iterencode
    return _iterencode(o, 0)
  File "/usr/local/lib/python3.9/site-packages/rest_framework/utils/encoders.py", line 67, in default
    return super().default(obj)
  File "/usr/local/lib/python3.9/json/encoder.py", line 179, in default
    raise TypeError(f'Object of type {o.__class__.__name__} '
TypeError: Object of type Symptom is not JSON serializable
[2022-08-03 04:51:11,326] ERROR [django.request.log_response:241] Internal Server Error: /doctor/health-records/
Traceback (most recent call last):
  File "/usr/local/lib/python3.9/site-packages/django/core/handlers/exception.py", line 55, in inner
    response = get_response(request)
  File "/usr/local/lib/python3.9/site-packages/django/core/handlers/base.py", line 220, in _get_response
    response = response.render()
  File "/usr/local/lib/python3.9/site-packages/django/template/response.py", line 114, in render
    self.content = self.rendered_content
  File "/usr/local/lib/python3.9/site-packages/rest_framework/response.py", line 70, in rendered_content
    ret = renderer.render(self.data, accepted_media_type, context)
  File "/usr/local/lib/python3.9/site-packages/rest_framework/renderers.py", line 100, in render
    ret = json.dumps(
  File "/usr/local/lib/python3.9/site-packages/rest_framework/utils/json.py", line 25, in dumps
    return json.dumps(*args, **kwargs)
  File "/usr/local/lib/python3.9/json/__init__.py", line 234, in dumps
    return cls(
  File "/usr/local/lib/python3.9/json/encoder.py", line 199, in encode
    chunks = self.iterencode(o, _one_shot=True)
  File "/usr/local/lib/python3.9/json/encoder.py", line 257, in iterencode
    return _iterencode(o, 0)
  File "/usr/local/lib/python3.9/site-packages/rest_framework/utils/encoders.py", line 67, in default
    return super().default(obj)
  File "/usr/local/lib/python3.9/json/encoder.py", line 179, in default
    raise TypeError(f'Object of type {o.__class__.__name__} '
TypeError: Object of type Symptom is not JSON serializable
[2022-08-03 04:52:37,303] WARNING [django.request.log_response:241] Bad Request: /doctor/health-records/
[2022-08-03 04:52:54,545] WARNING [django.request.log_response:241] Bad Request: /doctor/health-records/
[2022-08-03 04:53:06,830] WARNING [django.request.log_response:241] Bad Request: /doctor/health-records/
[2022-08-03 04:55:40,468] WARNING [django.request.log_response:241] Bad Request: /doctor/health-records/
[2022-08-03 11:35:45,641] WARNING [django.request.log_response:241] Unauthorized: /health-records/1/
