[2022-12-16 02:00:00,504] WARNING [django_apscheduler.util.func_wrapper:100] DB error executing '_get_jobs' ((2006, "MySQL server has gone away (BrokenPipeError(32, 'Broken pipe'))")). Retrying with a new DB connection...
[2022-12-16 02:00:01,275] WARNING [apscheduler.executors.default.run_job:120] Run time of job "remove_expired_nonsign_contract (trigger: cron[month='*', day='*', day_of_week='*', hour='2', minute='0'], next run at: 2022-12-16 02:00:00 UTC)" was missed by 0:00:01.275173
[2022-12-16 02:45:18,851] ERROR [django.request.log_response:241] Internal Server Error: /send-me/
[2022-12-16 05:00:00,548] WARNING [django_apscheduler.util.func_wrapper:100] DB error executing '_get_jobs' ((2006, "MySQL server has gone away (BrokenPipeError(32, 'Broken pipe'))")). Retrying with a new DB connection...
[2022-12-16 05:28:15,048] WARNING [django.request.log_response:241] Not Found: /favicon.ico
[2022-12-16 06:19:54,724] WARNING [django.request.log_response:241] Not Found: /http:/api.ipify.org/
[2022-12-16 06:20:17,775] WARNING [django.request.log_response:241] Not Found: /www.shadowserver.org:443
[2022-12-16 06:22:15,760] WARNING [django.request.log_response:241] Not Found: /favicon.ico
[2022-12-16 10:02:38,724] ERROR [django.request.log_response:241] Internal Server Error: /user/health-records/
[2022-12-16 10:03:34,373] WARNING [django.request.log_response:241] Bad Request: /user/health-records/
[2022-12-16 10:05:19,800] WARNING [django.request.log_response:241] Bad Request: /user/health-records/
[2022-12-16 10:06:32,485] WARNING [django.request.log_response:241] Bad Request: /user/health-records/
[2022-12-16 10:06:34,632] WARNING [django.request.log_response:241] Bad Request: /user/health-records/
[2022-12-16 10:08:24,923] WARNING [django.request.log_response:241] Bad Request: /user/health-records/
[2022-12-16 10:09:45,338] WARNING [django.request.log_response:241] Bad Request: /user/health-records/
[2022-12-16 10:10:23,289] WARNING [django.request.log_response:241] Bad Request: /user/health-records/
[2022-12-16 10:11:14,163] WARNING [django.request.log_response:241] Bad Request: /user/health-records/
[2022-12-16 10:18:35,995] WARNING [django.request.log_response:241] Bad Request: /user/health-records/
[2022-12-16 10:19:03,965] WARNING [django.request.log_response:241] Bad Request: /user/health-records/
[2022-12-16 10:20:07,690] WARNING [django.request.log_response:241] Bad Request: /user/health-records/
[2022-12-16 10:21:18,085] WARNING [django.request.log_response:241] Bad Request: /user/health-records/
[2022-12-16 10:21:57,190] WARNING [django.request.log_response:241] Bad Request: /user/health-records/
[2022-12-16 10:23:01,167] WARNING [django.request.log_response:241] Bad Request: /user/health-records/
[2022-12-16 10:23:32,944] WARNING [django.request.log_response:241] Bad Request: /user/health-records/
[2022-12-16 10:25:01,218] WARNING [django.request.log_response:241] Bad Request: /user/health-records/
[2022-12-16 10:26:46,134] WARNING [django.request.log_response:241] Bad Request: /user/health-records/
[2022-12-16 10:27:32,290] WARNING [django.request.log_response:241] Bad Request: /user/health-records/
[2022-12-16 10:29:01,075] WARNING [django.request.log_response:241] Bad Request: /user/health-records/
[2022-12-16 10:34:23,360] WARNING [django.request.log_response:241] Bad Request: /user/health-records/
[2022-12-16 10:36:32,935] WARNING [django.request.log_response:241] Bad Request: /user/health-records/
[2022-12-16 10:38:47,566] WARNING [django.request.log_response:241] Bad Request: /user/health-records/
[2022-12-16 10:43:33,514] ERROR [shared.exception_handler.__handle_attribute_error:122] 'NoneType' object has no attribute 'strftime'
[2022-12-16 10:43:33,517] ERROR [django.request.log_response:241] Internal Server Error: /user/health-records/
[2022-12-16 10:54:49,978] ERROR [django.request.log_response:241] Internal Server Error: /user/health-records/
[2022-12-16 10:55:23,922] ERROR [django.request.log_response:241] Internal Server Error: /user/health-records/
[2022-12-16 10:56:35,559] ERROR [django.request.log_response:241] Internal Server Error: /user/health-records/
[2022-12-16 10:57:32,932] ERROR [django.request.log_response:241] Internal Server Error: /user/health-records/
[2022-12-16 10:58:33,031] ERROR [django.request.log_response:241] Internal Server Error: /user/health-records/
[2022-12-16 11:00:41,533] ERROR [django.request.log_response:241] Internal Server Error: /user/health-records/
[2022-12-16 11:01:19,704] ERROR [django.request.log_response:241] Internal Server Error: /user/health-records/
[2022-12-16 11:05:04,106] ERROR [django.request.log_response:241] Internal Server Error: /user/health-records/
[2022-12-16 11:05:36,501] ERROR [django.request.log_response:241] Internal Server Error: /user/health-records/
[2022-12-16 11:06:06,396] ERROR [django.request.log_response:241] Internal Server Error: /user/health-records/
[2022-12-16 11:06:36,031] ERROR [django.request.log_response:241] Internal Server Error: /user/health-records/
[2022-12-16 11:13:23,730] ERROR [django.request.log_response:241] Internal Server Error: /user/health-records/
[2022-12-16 11:16:38,434] ERROR [django.request.log_response:241] Internal Server Error: /user/health-records/
[2022-12-16 11:17:50,605] ERROR [shared.exception_handler.__handle_attribute_error:122] 'HealthRecord' object has no attribute 'prescription'
[2022-12-16 11:17:50,609] ERROR [django.request.log_response:241] Internal Server Error: /user/health-records/
[2022-12-16 11:20:24,565] ERROR [shared.exception_handler.__handle_attribute_error:122] 'NoneType' object has no attribute 'name'
[2022-12-16 11:20:24,568] ERROR [django.request.log_response:241] Internal Server Error: /user/health-records/
[2022-12-16 11:24:07,410] ERROR [django.request.log_response:241] Internal Server Error: /user/health-records/
[2022-12-16 11:25:07,071] ERROR [shared.exception_handler.__handle_attribute_error:122] 'NoneType' object has no attribute 'name'
[2022-12-16 11:25:07,074] ERROR [django.request.log_response:241] Internal Server Error: /user/health-records/
[2022-12-16 11:26:11,021] ERROR [shared.exception_handler.__handle_attribute_error:122] 'NoneType' object has no attribute 'name'
[2022-12-16 11:26:11,028] ERROR [django.request.log_response:241] Internal Server Error: /user/health-records/
[2022-12-16 11:27:41,916] ERROR [shared.exception_handler.__handle_attribute_error:122] 'Logger' object has no attribute 'infor'
[2022-12-16 11:27:41,919] ERROR [django.request.log_response:241] Internal Server Error: /user/health-records/
[2022-12-16 11:27:59,483] ERROR [shared.exception_handler.__handle_attribute_error:122] 'NoneType' object has no attribute 'name'
[2022-12-16 11:27:59,487] ERROR [django.request.log_response:241] Internal Server Error: /user/health-records/
[2022-12-16 11:33:51,469] ERROR [shared.exception_handler.__handle_attribute_error:122] 'NoneType' object has no attribute 'name'
[2022-12-16 11:33:51,473] ERROR [django.request.log_response:241] Internal Server Error: /user/health-records/
[2022-12-16 11:34:46,333] ERROR [shared.exception_handler.__handle_attribute_error:122] 'NoneType' object has no attribute 'name'
[2022-12-16 11:34:46,336] ERROR [django.request.log_response:241] Internal Server Error: /user/health-records/
[2022-12-16 11:36:00,697] ERROR [shared.exception_handler.__handle_attribute_error:122] 'NoneType' object has no attribute 'name'
[2022-12-16 11:36:00,698] ERROR [django.request.log_response:241] Internal Server Error: /user/health-records/
[2022-12-16 11:37:53,123] ERROR [django.request.log_response:241] Internal Server Error: /user/health-records/
[2022-12-16 11:40:57,250] ERROR [shared.exception_handler.__handle_attribute_error:122] 'NoneType' object has no attribute 'name'
[2022-12-16 11:40:57,257] ERROR [django.request.log_response:241] Internal Server Error: /user/health-records/
[2022-12-16 11:41:45,313] ERROR [django.request.log_response:241] Internal Server Error: /user/health-records/
[2022-12-16 11:33:37,341] WARNING [django.request.log_response:241] Forbidden: /user/health-records/
[2022-12-16 12:01:19,885] WARNING [django.request.log_response:241] Unauthorized: /health-records/
[2022-12-16 12:15:28,351] WARNING [django.request.log_response:241] Bad Request: /appointments/
[2022-12-16 12:15:35,034] WARNING [django.request.log_response:241] Bad Request: /appointments/
[2022-12-16 12:15:43,195] WARNING [django.request.log_response:241] Bad Request: /appointments/
[2022-12-16 12:15:52,271] WARNING [django_apscheduler.util.func_wrapper:100] DB error executing '_get_jobs' ((2006, "MySQL server has gone away (BrokenPipeError(32, 'Broken pipe'))")). Retrying with a new DB connection...
[2022-12-16 18:04:18,415] WARNING [django.request.log_response:241] Forbidden: /prescription/
[2022-12-16 18:04:38,386] WARNING [django.request.log_response:241] Bad Request: /prescription/
[2022-12-16 18:04:47,757] WARNING [django.request.log_response:241] Bad Request: /prescription/
[2022-12-16 18:09:50,292] WARNING [django.request.log_response:241] Forbidden: /contract/
[2022-12-16 18:10:12,469] ERROR [django.request.log_response:241] Internal Server Error: /contract/
[2022-12-16 18:14:21,193] WARNING [django.request.log_response:241] Bad Request: /contract/
[2022-12-16 18:18:09,544] WARNING [django.request.log_response:241] Bad Request: /contract/
[2022-12-16 18:19:34,691] ERROR [django.request.log_response:241] Internal Server Error: /contract/
[2022-12-16 19:59:32,521] WARNING [django.request.log_response:241] Forbidden: /prescription/doctor/161/
[2022-12-16 19:59:47,904] WARNING [django.request.log_response:241] Forbidden: /prescription/doctor/160/
[2022-12-16 14:12:06,970] ERROR [django.request.log_response:241] Internal Server Error: /user/health-records/
[2022-12-16 14:13:03,771] ERROR [shared.exception_handler.__handle_attribute_error:122] 'NoneType' object has no attribute 'strftime'
[2022-12-16 14:13:03,774] ERROR [django.request.log_response:241] Internal Server Error: /user/health-records/
[2022-12-16 14:14:21,748] ERROR [shared.exception_handler.__handle_attribute_error:122] 'NoneType' object has no attribute 'strftime'
[2022-12-16 14:14:21,749] ERROR [django.request.log_response:241] Internal Server Error: /user/health-records/
[2022-12-16 14:41:54,321] ERROR [django.request.log_response:241] Internal Server Error: /user/health-records/
[2022-12-16 14:46:50,822] ERROR [django.request.log_response:241] Internal Server Error: /user/health-records/
[2022-12-16 14:59:44,632] ERROR [django.request.log_response:241] Internal Server Error: /user/health-records/
[2022-12-16 15:00:32,523] ERROR [django.request.log_response:241] Internal Server Error: /user/health-records/
[2022-12-16 17:36:09,915] WARNING [django.request.log_response:241] Bad Request: /user/health-records/
[2022-12-16 17:36:54,434] WARNING [django.request.log_response:241] Bad Request: /user/health-records/
[2022-12-16 17:42:15,049] ERROR [django.request.log_response:241] Internal Server Error: /user/health-records/
[2022-12-16 17:42:33,479] ERROR [django.request.log_response:241] Internal Server Error: /user/health-records/
[2022-12-16 18:13:19,201] ERROR [django.request.log_response:241] Internal Server Error: /user/health-records/
[2022-12-16 18:13:55,590] ERROR [django.request.log_response:241] Internal Server Error: /user/health-records/
[2022-12-16 18:14:47,152] ERROR [django.request.log_response:241] Internal Server Error: /user/health-records/
[2022-12-16 18:16:02,385] ERROR [django.request.log_response:241] Internal Server Error: /user/health-records/
[2022-12-16 18:18:34,045] ERROR [django.request.log_response:241] Internal Server Error: /health-records/180/
[2022-12-16 18:24:00,048] ERROR [django.request.log_response:241] Internal Server Error: /health-records/180/
Traceback (most recent call last):
  File "/usr/local/lib/python3.10/site-packages/django/core/handlers/exception.py", line 55, in inner
    response = get_response(request)
  File "/usr/local/lib/python3.10/site-packages/django/core/handlers/base.py", line 220, in _get_response
    response = response.render()
  File "/usr/local/lib/python3.10/site-packages/django/template/response.py", line 114, in render
    self.content = self.rendered_content
  File "/usr/local/lib/python3.10/site-packages/rest_framework/response.py", line 70, in rendered_content
    ret = renderer.render(self.data, accepted_media_type, context)
  File "/usr/local/lib/python3.10/site-packages/rest_framework/renderers.py", line 100, in render
    ret = json.dumps(
  File "/usr/local/lib/python3.10/site-packages/rest_framework/utils/json.py", line 25, in dumps
    return json.dumps(*args, **kwargs)
  File "/usr/local/lib/python3.10/json/__init__.py", line 238, in dumps
    **kw).encode(obj)
  File "/usr/local/lib/python3.10/json/encoder.py", line 199, in encode
    chunks = self.iterencode(o, _one_shot=True)
  File "/usr/local/lib/python3.10/json/encoder.py", line 257, in iterencode
    return _iterencode(o, 0)
  File "/usr/local/lib/python3.10/site-packages/rest_framework/utils/encoders.py", line 67, in default
    return super().default(obj)
  File "/usr/local/lib/python3.10/json/encoder.py", line 179, in default
    raise TypeError(f'Object of type {o.__class__.__name__} '
TypeError: Object of type ListSerializer is not JSON serializable
[2022-12-16 18:43:58,923] WARNING [django.request.log_response:241] Forbidden: /doctor/health-records/
[2022-12-16 18:44:17,633] WARNING [django.request.log_response:241] Bad Request: /doctor/health-records/
[2022-12-16 18:45:07,371] WARNING [django.request.log_response:241] Bad Request: /doctor/health-records/
[2022-12-16 18:46:43,156] WARNING [django.request.log_response:241] Bad Request: /doctor/health-records/
[2022-12-16 18:49:26,961] ERROR [django.request.log_response:241] Internal Server Error: /doctor/health-records/
[2022-12-16 18:53:19,996] ERROR [shared.exception_handler.__handle_attribute_error:122] 'NoneType' object has no attribute 'strftime'
[2022-12-16 18:53:20,003] ERROR [django.request.log_response:241] Internal Server Error: /doctor/health-records/
[2022-12-16 18:53:48,923] ERROR [django.request.log_response:241] Internal Server Error: /doctor/health-records/
Traceback (most recent call last):
  File "/usr/local/lib/python3.10/site-packages/django/core/handlers/exception.py", line 55, in inner
    response = get_response(request)
  File "/usr/local/lib/python3.10/site-packages/django/core/handlers/base.py", line 220, in _get_response
    response = response.render()
  File "/usr/local/lib/python3.10/site-packages/django/template/response.py", line 114, in render
    self.content = self.rendered_content
  File "/usr/local/lib/python3.10/site-packages/rest_framework/response.py", line 70, in rendered_content
    ret = renderer.render(self.data, accepted_media_type, context)
  File "/usr/local/lib/python3.10/site-packages/rest_framework/renderers.py", line 100, in render
    ret = json.dumps(
  File "/usr/local/lib/python3.10/site-packages/rest_framework/utils/json.py", line 25, in dumps
    return json.dumps(*args, **kwargs)
  File "/usr/local/lib/python3.10/json/__init__.py", line 238, in dumps
    **kw).encode(obj)
  File "/usr/local/lib/python3.10/json/encoder.py", line 199, in encode
    chunks = self.iterencode(o, _one_shot=True)
  File "/usr/local/lib/python3.10/json/encoder.py", line 257, in iterencode
    return _iterencode(o, 0)
  File "/usr/local/lib/python3.10/site-packages/rest_framework/utils/encoders.py", line 67, in default
    return super().default(obj)
  File "/usr/local/lib/python3.10/json/encoder.py", line 179, in default
    raise TypeError(f'Object of type {o.__class__.__name__} '
TypeError: Object of type Disease is not JSON serializable
[2022-12-16 19:04:59,290] WARNING [django.request.log_response:241] Not Found: /favicon.ico
[2022-12-16 19:15:56,530] WARNING [django.request.log_response:241] Forbidden: /user/health-records/
