[2022-09-25 06:28:45,383] WARNING [django.request.log_response:241] Not Found: /favicon.ico
[2022-09-25 07:00:39,643] ERROR [django.request.log_response:241] Internal Server Error: /doctor/5/packages/
[2022-09-25 07:01:09,486] ERROR [django.request.log_response:241] Internal Server Error: /doctor/5/packages/
[2022-09-25 07:01:51,809] ERROR [django.request.log_response:241] Internal Server Error: /doctor/5/packages/
[2022-09-25 07:10:24,638] ERROR [shared.exception_handler.__handle_attribute_error:122] 'ListCreatePackageView' object has no attribute 'action'
[2022-09-25 07:10:24,642] ERROR [django.request.log_response:241] Internal Server Error: /doctor/5/packages/
[2022-09-25 07:12:32,375] WARNING [django.request.log_response:241] Forbidden: /doctor/5/packages/
[2022-09-25 07:37:33,739] ERROR [django.request.log_response:241] Internal Server Error: /doctor/6/packages/
[2022-09-25 07:38:33,924] ERROR [django.request.log_response:241] Internal Server Error: /doctor/6/packages/
Traceback (most recent call last):
  File "/usr/local/lib/python3.10/site-packages/django/core/handlers/exception.py", line 55, in inner
    response = get_response(request)
  File "/usr/local/lib/python3.10/site-packages/django/core/handlers/base.py", line 220, in _get_response
    response = response.render()
  File "/usr/local/lib/python3.10/site-packages/django/template/response.py", line 114, in render
    self.content = self.rendered_content
  File "/usr/local/lib/python3.10/site-packages/rest_framework/response.py", line 70, in rendered_content
    ret = renderer.render(self.data, accepted_media_type, context)
  File "/usr/local/lib/python3.10/site-packages/rest_framework/renderers.py", line 100, in render
    ret = json.dumps(
  File "/usr/local/lib/python3.10/site-packages/rest_framework/utils/json.py", line 25, in dumps
    return json.dumps(*args, **kwargs)
  File "/usr/local/lib/python3.10/json/__init__.py", line 238, in dumps
    **kw).encode(obj)
  File "/usr/local/lib/python3.10/json/encoder.py", line 199, in encode
    chunks = self.iterencode(o, _one_shot=True)
  File "/usr/local/lib/python3.10/json/encoder.py", line 257, in iterencode
    return _iterencode(o, 0)
  File "/usr/local/lib/python3.10/site-packages/rest_framework/utils/encoders.py", line 67, in default
    return super().default(obj)
  File "/usr/local/lib/python3.10/json/encoder.py", line 179, in default
    raise TypeError(f'Object of type {o.__class__.__name__} '
TypeError: Object of type Package is not JSON serializable
[2022-09-25 07:52:45,337] WARNING [django.request.log_response:241] Forbidden: /appointments/
[2022-09-25 07:53:01,781] WARNING [django.request.log_response:241] Bad Request: /appointments/
[2022-09-25 07:53:38,529] ERROR [django.request.log_response:241] Internal Server Error: /appointments/
[2022-09-25 07:56:47,838] ERROR [django.request.log_response:241] Internal Server Error: /appointments/
[2022-09-25 08:01:44,720] ERROR [django.request.log_response:241] Internal Server Error: /appointments/
[2022-09-25 08:02:58,479] ERROR [django.request.log_response:241] Internal Server Error: /appointments/
[2022-09-25 08:06:36,912] ERROR [django.request.log_response:241] Internal Server Error: /appointments/
[2022-09-25 08:08:17,699] WARNING [django.request.log_response:241] Bad Request: /appointments/
[2022-09-25 08:08:25,136] WARNING [django.request.log_response:241] Bad Request: /appointments/
[2022-09-25 08:08:31,259] WARNING [django.request.log_response:241] Bad Request: /appointments/
[2022-09-25 08:08:41,518] WARNING [django.request.log_response:241] Bad Request: /appointments/
[2022-09-25 08:08:47,502] WARNING [django.request.log_response:241] Bad Request: /appointments/
[2022-09-25 08:09:07,186] WARNING [django.request.log_response:241] Bad Request: /appointments/
[2022-09-25 08:09:11,512] WARNING [django.request.log_response:241] Bad Request: /appointments/
[2022-09-25 08:09:25,070] WARNING [django.request.log_response:241] Bad Request: /appointments/
[2022-09-25 08:09:57,649] WARNING [django.request.log_response:241] Bad Request: /appointments/
[2022-09-25 08:10:22,159] ERROR [shared.exception_handler.__handle_attribute_error:122] 'NoneType' object has no attribute 'pk'
[2022-09-25 08:10:22,161] ERROR [django.request.log_response:241] Internal Server Error: /appointments/
[2022-09-25 08:11:49,598] ERROR [shared.exception_handler.__handle_attribute_error:122] 'NoneType' object has no attribute 'pk'
[2022-09-25 08:11:49,601] ERROR [django.request.log_response:241] Internal Server Error: /appointments/
[2022-09-25 08:12:43,551] ERROR [shared.exception_handler.__handle_attribute_error:122] 'NoneType' object has no attribute 'pk'
[2022-09-25 08:12:43,552] ERROR [django.request.log_response:241] Internal Server Error: /appointments/
[2022-09-25 08:12:55,588] ERROR [shared.exception_handler.__handle_attribute_error:122] 'NoneType' object has no attribute 'pk'
[2022-09-25 08:12:55,592] ERROR [django.request.log_response:241] Internal Server Error: /appointments/
[2022-09-25 08:13:01,239] ERROR [shared.exception_handler.__handle_attribute_error:122] 'NoneType' object has no attribute 'pk'
[2022-09-25 08:13:01,241] ERROR [django.request.log_response:241] Internal Server Error: /appointments/
[2022-09-25 08:13:38,446] ERROR [shared.exception_handler.__handle_attribute_error:122] 'NoneType' object has no attribute 'pk'
[2022-09-25 08:13:38,456] ERROR [django.request.log_response:241] Internal Server Error: /appointments/
[2022-09-25 08:14:27,627] ERROR [shared.exception_handler.__handle_attribute_error:122] 'NoneType' object has no attribute 'pk'
[2022-09-25 08:14:27,631] ERROR [django.request.log_response:241] Internal Server Error: /appointments/
[2022-09-25 08:37:16,708] WARNING [django.request.log_response:241] Forbidden: /appointments/doctor/
[2022-09-25 08:45:59,582] ERROR [django.request.log_response:241] Internal Server Error: /appointments/doctor/
