[2022-07-16 06:22:27,817] WARNING [django.request.log_response:241] Not Found: /admin.
[2022-07-16 06:22:27,927] WARNING [django.request.log_response:241] Not Found: /favicon.ico
[2022-07-16 06:36:47,100] WARNING [django.request.log_response:241] Unauthorized: /doctor/1/
[2022-07-16 06:36:56,619] WARNING [django.request.log_response:241] Unauthorized: /doctor/1/
[2022-07-16 06:37:55,424] ERROR [django.request.log_response:241] Internal Server Error: /doctor/1/
[2022-07-16 06:39:57,993] ERROR [django.request.log_response:241] Internal Server Error: /doctor/1/
[2022-07-16 06:41:20,004] WARNING [django.request.log_response:241] Not Found: /doctor/1/
[2022-07-16 06:43:17,412] ERROR [django.request.log_response:241] Internal Server Error: /doctor/1/
[2022-07-16 06:43:38,103] ERROR [django.request.log_response:241] Internal Server Error: /doctor/1/
[2022-07-16 06:49:32,727] ERROR [django.request.log_response:241] Internal Server Error: /doctor/1/
[2022-07-16 06:52:00,976] ERROR [shared.exception_handler.__handle_http404:111] 
[2022-07-16 06:52:01,729] ERROR [django.request.log_response:241] Internal Server Error: /doctor/1/
Traceback (most recent call last):
  File "/usr/local/lib/python3.9/site-packages/rest_framework/generics.py", line 19, in get_object_or_404
    return _get_object_or_404(queryset, *filter_args, **filter_kwargs)
  File "/usr/local/lib/python3.9/site-packages/django/shortcuts.py", line 85, in get_object_or_404
    return queryset.get(*args, **kwargs)
  File "/usr/local/lib/python3.9/site-packages/django/db/models/query.py", line 492, in get
    num = len(clone)
  File "/usr/local/lib/python3.9/site-packages/django/db/models/query.py", line 302, in __len__
    self._fetch_all()
  File "/usr/local/lib/python3.9/site-packages/django/db/models/query.py", line 1509, in _fetch_all
    self._prefetch_related_objects()
  File "/usr/local/lib/python3.9/site-packages/django/db/models/query.py", line 915, in _prefetch_related_objects
    prefetch_related_objects(self._result_cache, *self._prefetch_related_lookups)
  File "/usr/local/lib/python3.9/site-packages/django/db/models/query.py", line 1960, in prefetch_related_objects
    obj_list, additional_lookups = prefetch_one_level(
  File "/usr/local/lib/python3.9/site-packages/django/db/models/query.py", line 2138, in prefetch_one_level
    raise ValueError(msg.format(to_attr, model.__name__))
ValueError: to_attr=specs conflicts with a field on the Doctor model.

During handling of the above exception, another exception occurred:

Traceback (most recent call last):
  File "/usr/local/lib/python3.9/site-packages/rest_framework/views.py", line 506, in dispatch
    response = handler(request, *args, **kwargs)
  File "/usr/local/lib/python3.9/site-packages/rest_framework/generics.py", line 208, in get
    return self.retrieve(request, *args, **kwargs)
  File "/usr/src/app/doctor/views.py", line 43, in retrieve
    doctor: Doctor = self.get_object()
  File "/usr/local/lib/python3.9/site-packages/rest_framework/generics.py", line 96, in get_object
    obj = get_object_or_404(queryset, **filter_kwargs)
  File "/usr/local/lib/python3.9/site-packages/rest_framework/generics.py", line 21, in get_object_or_404
    raise Http404
django.http.response.Http404

During handling of the above exception, another exception occurred:

Traceback (most recent call last):
  File "/usr/local/lib/python3.9/site-packages/django/core/handlers/exception.py", line 55, in inner
    response = get_response(request)
  File "/usr/local/lib/python3.9/site-packages/django/core/handlers/base.py", line 197, in _get_response
    response = wrapped_callback(request, *callback_args, **callback_kwargs)
  File "/usr/local/lib/python3.9/site-packages/django/views/decorators/csrf.py", line 54, in wrapped_view
    return view_func(*args, **kwargs)
  File "/usr/local/lib/python3.9/site-packages/django/views/generic/base.py", line 84, in view
    return self.dispatch(request, *args, **kwargs)
  File "/usr/local/lib/python3.9/site-packages/rest_framework/views.py", line 509, in dispatch
    response = self.handle_exception(exc)
  File "/usr/local/lib/python3.9/site-packages/rest_framework/views.py", line 466, in handle_exception
    response = exception_handler(exc, context)
  File "/usr/src/app/shared/exception_handler.py", line 153, in custom_exception_handler
    return cached_exceptions[exception_name](exc, context)
  File "/usr/src/app/shared/exception_handler.py", line 115, in __handle_http404
    message = exc.detail
AttributeError: 'Http404' object has no attribute 'detail'
[2022-07-16 06:53:20,821] ERROR [django.request.log_response:241] Internal Server Error: /doctor/1/
[2022-07-16 06:57:25,427] ERROR [django.request.log_response:241] Internal Server Error: /doctor/1/
Traceback (most recent call last):
  File "/usr/local/lib/python3.9/site-packages/django/core/handlers/exception.py", line 55, in inner
    response = get_response(request)
  File "/usr/local/lib/python3.9/site-packages/django/core/handlers/base.py", line 220, in _get_response
    response = response.render()
  File "/usr/local/lib/python3.9/site-packages/django/template/response.py", line 114, in render
    self.content = self.rendered_content
  File "/usr/local/lib/python3.9/site-packages/rest_framework/response.py", line 70, in rendered_content
    ret = renderer.render(self.data, accepted_media_type, context)
  File "/usr/local/lib/python3.9/site-packages/rest_framework/renderers.py", line 100, in render
    ret = json.dumps(
  File "/usr/local/lib/python3.9/site-packages/rest_framework/utils/json.py", line 25, in dumps
    return json.dumps(*args, **kwargs)
  File "/usr/local/lib/python3.9/json/__init__.py", line 234, in dumps
    return cls(
  File "/usr/local/lib/python3.9/json/encoder.py", line 199, in encode
    chunks = self.iterencode(o, _one_shot=True)
  File "/usr/local/lib/python3.9/json/encoder.py", line 257, in iterencode
    return _iterencode(o, 0)
  File "/usr/local/lib/python3.9/site-packages/rest_framework/utils/encoders.py", line 67, in default
    return super().default(obj)
  File "/usr/local/lib/python3.9/json/encoder.py", line 179, in default
    raise TypeError(f'Object of type {o.__class__.__name__} '
TypeError: Object of type DoctorSerializer is not JSON serializable
[2022-07-16 06:57:46,361] ERROR [django.request.log_response:241] Internal Server Error: /doctor/1/
Traceback (most recent call last):
  File "/usr/local/lib/python3.9/site-packages/django/core/handlers/exception.py", line 55, in inner
    response = get_response(request)
  File "/usr/local/lib/python3.9/site-packages/django/core/handlers/base.py", line 220, in _get_response
    response = response.render()
  File "/usr/local/lib/python3.9/site-packages/django/template/response.py", line 114, in render
    self.content = self.rendered_content
  File "/usr/local/lib/python3.9/site-packages/rest_framework/response.py", line 70, in rendered_content
    ret = renderer.render(self.data, accepted_media_type, context)
  File "/usr/local/lib/python3.9/site-packages/rest_framework/renderers.py", line 100, in render
    ret = json.dumps(
  File "/usr/local/lib/python3.9/site-packages/rest_framework/utils/json.py", line 25, in dumps
    return json.dumps(*args, **kwargs)
  File "/usr/local/lib/python3.9/json/__init__.py", line 234, in dumps
    return cls(
  File "/usr/local/lib/python3.9/json/encoder.py", line 199, in encode
    chunks = self.iterencode(o, _one_shot=True)
  File "/usr/local/lib/python3.9/json/encoder.py", line 257, in iterencode
    return _iterencode(o, 0)
  File "/usr/local/lib/python3.9/site-packages/rest_framework/utils/encoders.py", line 67, in default
    return super().default(obj)
  File "/usr/local/lib/python3.9/json/encoder.py", line 179, in default
    raise TypeError(f'Object of type {o.__class__.__name__} '
TypeError: Object of type Doctor is not JSON serializable
[2022-07-16 06:58:07,994] ERROR [django.request.log_response:241] Internal Server Error: /doctor/1/
Traceback (most recent call last):
  File "/usr/local/lib/python3.9/site-packages/django/core/handlers/exception.py", line 55, in inner
    response = get_response(request)
  File "/usr/local/lib/python3.9/site-packages/django/core/handlers/base.py", line 220, in _get_response
    response = response.render()
  File "/usr/local/lib/python3.9/site-packages/django/template/response.py", line 114, in render
    self.content = self.rendered_content
  File "/usr/local/lib/python3.9/site-packages/rest_framework/response.py", line 70, in rendered_content
    ret = renderer.render(self.data, accepted_media_type, context)
  File "/usr/local/lib/python3.9/site-packages/rest_framework/renderers.py", line 100, in render
    ret = json.dumps(
  File "/usr/local/lib/python3.9/site-packages/rest_framework/utils/json.py", line 25, in dumps
    return json.dumps(*args, **kwargs)
  File "/usr/local/lib/python3.9/json/__init__.py", line 234, in dumps
    return cls(
  File "/usr/local/lib/python3.9/json/encoder.py", line 199, in encode
    chunks = self.iterencode(o, _one_shot=True)
  File "/usr/local/lib/python3.9/json/encoder.py", line 257, in iterencode
    return _iterencode(o, 0)
  File "/usr/local/lib/python3.9/site-packages/rest_framework/utils/encoders.py", line 67, in default
    return super().default(obj)
  File "/usr/local/lib/python3.9/json/encoder.py", line 179, in default
    raise TypeError(f'Object of type {o.__class__.__name__} '
TypeError: Object of type ModelState is not JSON serializable
[2022-07-16 06:59:01,309] ERROR [django.request.log_response:241] Internal Server Error: /doctor/1/
[2022-07-16 07:00:45,423] ERROR [django.request.log_response:241] Internal Server Error: /doctor/1/
[2022-07-16 07:05:14,769] ERROR [django.request.log_response:241] Internal Server Error: /doctor/1/
[2022-07-16 07:06:37,617] ERROR [shared.exception_handler.__handle_http404:111] 
[2022-07-16 07:06:37,986] ERROR [django.request.log_response:241] Internal Server Error: /doctor/12/
Traceback (most recent call last):
  File "/usr/src/app/doctor/views.py", line 45, in get_object
    return Doctor.objects \
  File "/usr/local/lib/python3.9/site-packages/django/db/models/query.py", line 496, in get
    raise self.model.DoesNotExist(
doctor.models.Doctor.DoesNotExist: Doctor matching query does not exist.

During handling of the above exception, another exception occurred:

Traceback (most recent call last):
  File "/usr/local/lib/python3.9/site-packages/rest_framework/views.py", line 506, in dispatch
    response = handler(request, *args, **kwargs)
  File "/usr/local/lib/python3.9/site-packages/rest_framework/generics.py", line 208, in get
    return self.retrieve(request, *args, **kwargs)
  File "/usr/src/app/doctor/views.py", line 58, in retrieve
    doctor: Doctor = self.get_object(kwargs.pop('pk'))
  File "/usr/src/app/doctor/views.py", line 55, in get_object
    raise Http404
django.http.response.Http404

During handling of the above exception, another exception occurred:

Traceback (most recent call last):
  File "/usr/local/lib/python3.9/site-packages/django/core/handlers/exception.py", line 55, in inner
    response = get_response(request)
  File "/usr/local/lib/python3.9/site-packages/django/core/handlers/base.py", line 197, in _get_response
    response = wrapped_callback(request, *callback_args, **callback_kwargs)
  File "/usr/local/lib/python3.9/site-packages/django/views/decorators/csrf.py", line 54, in wrapped_view
    return view_func(*args, **kwargs)
  File "/usr/local/lib/python3.9/site-packages/django/views/generic/base.py", line 84, in view
    return self.dispatch(request, *args, **kwargs)
  File "/usr/local/lib/python3.9/site-packages/rest_framework/views.py", line 509, in dispatch
    response = self.handle_exception(exc)
  File "/usr/local/lib/python3.9/site-packages/rest_framework/views.py", line 466, in handle_exception
    response = exception_handler(exc, context)
  File "/usr/src/app/shared/exception_handler.py", line 153, in custom_exception_handler
    return cached_exceptions[exception_name](exc, context)
  File "/usr/src/app/shared/exception_handler.py", line 115, in __handle_http404
    message = exc.detail
AttributeError: 'Http404' object has no attribute 'detail'
[2022-07-16 07:07:35,534] ERROR [shared.exception_handler.__handle_http404:111] 
[2022-07-16 07:07:35,536] WARNING [django.request.log_response:241] Not Found: /doctor/12/
[2022-07-16 07:08:44,531] ERROR [shared.exception_handler.__handle_http404:111] 
[2022-07-16 07:08:44,535] WARNING [django.request.log_response:241] Not Found: /doctor/12/
[2022-07-16 07:08:47,282] ERROR [shared.exception_handler.__handle_http404:111] 
[2022-07-16 07:08:47,284] WARNING [django.request.log_response:241] Not Found: /doctor/12/
[2022-07-16 07:10:03,381] ERROR [shared.exception_handler.__handle_http404:111] 
[2022-07-16 07:10:03,385] WARNING [django.request.log_response:241] Not Found: /doctor/12/
[2022-07-16 07:14:33,600] ERROR [django.request.log_response:241] Internal Server Error: /doctor/1/
[2022-07-16 07:15:13,668] ERROR [django.request.log_response:241] Internal Server Error: /doctor/1/
[2022-07-16 07:26:15,883] ERROR [django.request.log_response:241] Internal Server Error: /doctor/1/
[2022-07-16 07:46:26,941] ERROR [django.request.log_response:241] Internal Server Error: /doctor/1/
Traceback (most recent call last):
  File "/usr/local/lib/python3.9/site-packages/django/core/handlers/exception.py", line 55, in inner
    response = get_response(request)
  File "/usr/local/lib/python3.9/site-packages/django/core/handlers/base.py", line 220, in _get_response
    response = response.render()
  File "/usr/local/lib/python3.9/site-packages/django/template/response.py", line 114, in render
    self.content = self.rendered_content
  File "/usr/local/lib/python3.9/site-packages/rest_framework/response.py", line 70, in rendered_content
    ret = renderer.render(self.data, accepted_media_type, context)
  File "/usr/local/lib/python3.9/site-packages/rest_framework/renderers.py", line 100, in render
    ret = json.dumps(
  File "/usr/local/lib/python3.9/site-packages/rest_framework/utils/json.py", line 25, in dumps
    return json.dumps(*args, **kwargs)
  File "/usr/local/lib/python3.9/json/__init__.py", line 234, in dumps
    return cls(
  File "/usr/local/lib/python3.9/json/encoder.py", line 199, in encode
    chunks = self.iterencode(o, _one_shot=True)
  File "/usr/local/lib/python3.9/json/encoder.py", line 257, in iterencode
    return _iterencode(o, 0)
  File "/usr/local/lib/python3.9/site-packages/rest_framework/utils/encoders.py", line 67, in default
    return super().default(obj)
  File "/usr/local/lib/python3.9/json/encoder.py", line 179, in default
    raise TypeError(f'Object of type {o.__class__.__name__} '
TypeError: Object of type RelatedManager is not JSON serializable
[2022-07-16 07:47:01,162] ERROR [django.request.log_response:241] Internal Server Error: /doctor/1/
Traceback (most recent call last):
  File "/usr/local/lib/python3.9/site-packages/django/core/handlers/exception.py", line 55, in inner
    response = get_response(request)
  File "/usr/local/lib/python3.9/site-packages/django/core/handlers/base.py", line 220, in _get_response
    response = response.render()
  File "/usr/local/lib/python3.9/site-packages/django/template/response.py", line 114, in render
    self.content = self.rendered_content
  File "/usr/local/lib/python3.9/site-packages/rest_framework/response.py", line 70, in rendered_content
    ret = renderer.render(self.data, accepted_media_type, context)
  File "/usr/local/lib/python3.9/site-packages/rest_framework/renderers.py", line 100, in render
    ret = json.dumps(
  File "/usr/local/lib/python3.9/site-packages/rest_framework/utils/json.py", line 25, in dumps
    return json.dumps(*args, **kwargs)
  File "/usr/local/lib/python3.9/json/__init__.py", line 234, in dumps
    return cls(
  File "/usr/local/lib/python3.9/json/encoder.py", line 199, in encode
    chunks = self.iterencode(o, _one_shot=True)
  File "/usr/local/lib/python3.9/json/encoder.py", line 257, in iterencode
    return _iterencode(o, 0)
  File "/usr/local/lib/python3.9/site-packages/rest_framework/utils/encoders.py", line 67, in default
    return super().default(obj)
  File "/usr/local/lib/python3.9/json/encoder.py", line 179, in default
    raise TypeError(f'Object of type {o.__class__.__name__} '
TypeError: Object of type RelatedManager is not JSON serializable
[2022-07-16 07:47:06,392] ERROR [django.request.log_response:241] Internal Server Error: /doctor/1/
Traceback (most recent call last):
  File "/usr/local/lib/python3.9/site-packages/django/core/handlers/exception.py", line 55, in inner
    response = get_response(request)
  File "/usr/local/lib/python3.9/site-packages/django/core/handlers/base.py", line 220, in _get_response
    response = response.render()
  File "/usr/local/lib/python3.9/site-packages/django/template/response.py", line 114, in render
    self.content = self.rendered_content
  File "/usr/local/lib/python3.9/site-packages/rest_framework/response.py", line 70, in rendered_content
    ret = renderer.render(self.data, accepted_media_type, context)
  File "/usr/local/lib/python3.9/site-packages/rest_framework/renderers.py", line 100, in render
    ret = json.dumps(
  File "/usr/local/lib/python3.9/site-packages/rest_framework/utils/json.py", line 25, in dumps
    return json.dumps(*args, **kwargs)
  File "/usr/local/lib/python3.9/json/__init__.py", line 234, in dumps
    return cls(
  File "/usr/local/lib/python3.9/json/encoder.py", line 199, in encode
    chunks = self.iterencode(o, _one_shot=True)
  File "/usr/local/lib/python3.9/json/encoder.py", line 257, in iterencode
    return _iterencode(o, 0)
  File "/usr/local/lib/python3.9/site-packages/rest_framework/utils/encoders.py", line 67, in default
    return super().default(obj)
  File "/usr/local/lib/python3.9/json/encoder.py", line 179, in default
    raise TypeError(f'Object of type {o.__class__.__name__} '
TypeError: Object of type RelatedManager is not JSON serializable
[2022-07-16 07:53:00,887] ERROR [django.request.log_response:241] Internal Server Error: /doctor/1/
[2022-07-16 07:56:19,362] ERROR [django.request.log_response:241] Internal Server Error: /doctor/register/
[2022-07-16 07:57:34,042] ERROR [shared.exception_handler.__handle_http404:111] 
[2022-07-16 07:57:34,043] WARNING [django.request.log_response:241] Not Found: /doctor/2/
[2022-07-16 07:58:27,695] ERROR [django.request.log_response:241] Internal Server Error: /doctor/3/
[2022-07-16 07:59:17,022] ERROR [django.request.log_response:241] Internal Server Error: /doctor/3/
Traceback (most recent call last):
  File "/usr/local/lib/python3.9/site-packages/django/core/handlers/exception.py", line 55, in inner
    response = get_response(request)
  File "/usr/local/lib/python3.9/site-packages/django/core/handlers/base.py", line 197, in _get_response
    response = wrapped_callback(request, *callback_args, **callback_kwargs)
  File "/usr/local/lib/python3.9/site-packages/django/views/decorators/csrf.py", line 54, in wrapped_view
    return view_func(*args, **kwargs)
  File "/usr/local/lib/python3.9/site-packages/django/views/generic/base.py", line 84, in view
    return self.dispatch(request, *args, **kwargs)
  File "/usr/local/lib/python3.9/site-packages/rest_framework/views.py", line 509, in dispatch
    response = self.handle_exception(exc)
  File "/usr/local/lib/python3.9/site-packages/rest_framework/views.py", line 469, in handle_exception
    self.raise_uncaught_exception(exc)
  File "/usr/local/lib/python3.9/site-packages/rest_framework/views.py", line 480, in raise_uncaught_exception
    raise exc
  File "/usr/local/lib/python3.9/site-packages/rest_framework/views.py", line 506, in dispatch
    response = handler(request, *args, **kwargs)
  File "/usr/local/lib/python3.9/site-packages/rest_framework/generics.py", line 208, in get
    return self.retrieve(request, *args, **kwargs)
  File "/usr/src/app/doctor/views.py", line 47, in retrieve
    doctor: Doctor = self.get_object(kwargs.pop('pk'))
  File "/usr/src/app/doctor/views.py", line 35, in get_object
    obj = Doctor.objects \
  File "/usr/local/lib/python3.9/site-packages/django/db/models/query.py", line 753, in first
    for obj in (self if self.ordered else self.order_by("pk"))[:1]:
  File "/usr/local/lib/python3.9/site-packages/django/db/models/query.py", line 320, in __iter__
    self._fetch_all()
  File "/usr/local/lib/python3.9/site-packages/django/db/models/query.py", line 1509, in _fetch_all
    self._prefetch_related_objects()
  File "/usr/local/lib/python3.9/site-packages/django/db/models/query.py", line 915, in _prefetch_related_objects
    prefetch_related_objects(self._result_cache, *self._prefetch_related_lookups)
  File "/usr/local/lib/python3.9/site-packages/django/db/models/query.py", line 1935, in prefetch_related_objects
    raise AttributeError(
AttributeError: Cannot find '' on Doctor object, '' is an invalid parameter to prefetch_related()
[2022-07-16 08:01:39,469] ERROR [django.request.log_response:241] Internal Server Error: /doctor/3/
Traceback (most recent call last):
  File "/usr/local/lib/python3.9/site-packages/django/core/handlers/exception.py", line 55, in inner
    response = get_response(request)
  File "/usr/local/lib/python3.9/site-packages/django/core/handlers/base.py", line 197, in _get_response
    response = wrapped_callback(request, *callback_args, **callback_kwargs)
  File "/usr/local/lib/python3.9/site-packages/django/views/decorators/csrf.py", line 54, in wrapped_view
    return view_func(*args, **kwargs)
  File "/usr/local/lib/python3.9/site-packages/django/views/generic/base.py", line 84, in view
    return self.dispatch(request, *args, **kwargs)
  File "/usr/local/lib/python3.9/site-packages/rest_framework/views.py", line 509, in dispatch
    response = self.handle_exception(exc)
  File "/usr/local/lib/python3.9/site-packages/rest_framework/views.py", line 469, in handle_exception
    self.raise_uncaught_exception(exc)
  File "/usr/local/lib/python3.9/site-packages/rest_framework/views.py", line 480, in raise_uncaught_exception
    raise exc
  File "/usr/local/lib/python3.9/site-packages/rest_framework/views.py", line 506, in dispatch
    response = handler(request, *args, **kwargs)
  File "/usr/local/lib/python3.9/site-packages/rest_framework/generics.py", line 208, in get
    return self.retrieve(request, *args, **kwargs)
  File "/usr/src/app/doctor/views.py", line 52, in retrieve
    doctor: Doctor = self.get_object(kwargs.pop('pk'))
  File "/usr/src/app/doctor/views.py", line 37, in get_object
    Prefetch(
TypeError: __init__() got an unexpected keyword argument 'lookups'
[2022-07-16 08:08:37,228] ERROR [django.request.log_response:241] Internal Server Error: /doctor/3/
Traceback (most recent call last):
  File "/usr/local/lib/python3.9/site-packages/django/core/handlers/exception.py", line 55, in inner
    response = get_response(request)
  File "/usr/local/lib/python3.9/site-packages/django/core/handlers/base.py", line 197, in _get_response
    response = wrapped_callback(request, *callback_args, **callback_kwargs)
  File "/usr/local/lib/python3.9/site-packages/django/views/decorators/csrf.py", line 54, in wrapped_view
    return view_func(*args, **kwargs)
  File "/usr/local/lib/python3.9/site-packages/django/views/generic/base.py", line 84, in view
    return self.dispatch(request, *args, **kwargs)
  File "/usr/local/lib/python3.9/site-packages/rest_framework/views.py", line 509, in dispatch
    response = self.handle_exception(exc)
  File "/usr/local/lib/python3.9/site-packages/rest_framework/views.py", line 469, in handle_exception
    self.raise_uncaught_exception(exc)
  File "/usr/local/lib/python3.9/site-packages/rest_framework/views.py", line 480, in raise_uncaught_exception
    raise exc
  File "/usr/local/lib/python3.9/site-packages/rest_framework/views.py", line 506, in dispatch
    response = handler(request, *args, **kwargs)
  File "/usr/local/lib/python3.9/site-packages/rest_framework/generics.py", line 208, in get
    return self.retrieve(request, *args, **kwargs)
  File "/usr/src/app/doctor/views.py", line 47, in retrieve
    doctor: Doctor = self.get_object(kwargs.pop('pk'))
  File "/usr/src/app/doctor/views.py", line 35, in get_object
    obj = Doctor.objects \
  File "/usr/local/lib/python3.9/site-packages/django/db/models/query.py", line 753, in first
    for obj in (self if self.ordered else self.order_by("pk"))[:1]:
  File "/usr/local/lib/python3.9/site-packages/django/db/models/query.py", line 320, in __iter__
    self._fetch_all()
  File "/usr/local/lib/python3.9/site-packages/django/db/models/query.py", line 1509, in _fetch_all
    self._prefetch_related_objects()
  File "/usr/local/lib/python3.9/site-packages/django/db/models/query.py", line 915, in _prefetch_related_objects
    prefetch_related_objects(self._result_cache, *self._prefetch_related_lookups)
  File "/usr/local/lib/python3.9/site-packages/django/db/models/query.py", line 1935, in prefetch_related_objects
    raise AttributeError(
AttributeError: Cannot find 'asdsd' on Doctor object, 'asdsd' is an invalid parameter to prefetch_related()
[2022-07-16 08:09:54,636] WARNING [django.request.log_response:241] Not Found: /doctor/3/
[2022-07-16 08:10:30,428] ERROR [shared.exception_handler.__handle_http404:111] 
[2022-07-16 08:10:30,432] WARNING [django.request.log_response:241] Not Found: /doctor/3/
[2022-07-16 08:12:43,488] ERROR [django.request.log_response:241] Internal Server Error: /doctor/3/
Traceback (most recent call last):
  File "/usr/local/lib/python3.9/site-packages/django/core/handlers/exception.py", line 55, in inner
    response = get_response(request)
  File "/usr/local/lib/python3.9/site-packages/django/core/handlers/base.py", line 197, in _get_response
    response = wrapped_callback(request, *callback_args, **callback_kwargs)
  File "/usr/local/lib/python3.9/site-packages/django/views/decorators/csrf.py", line 54, in wrapped_view
    return view_func(*args, **kwargs)
  File "/usr/local/lib/python3.9/site-packages/django/views/generic/base.py", line 84, in view
    return self.dispatch(request, *args, **kwargs)
  File "/usr/local/lib/python3.9/site-packages/rest_framework/views.py", line 509, in dispatch
    response = self.handle_exception(exc)
  File "/usr/local/lib/python3.9/site-packages/rest_framework/views.py", line 469, in handle_exception
    self.raise_uncaught_exception(exc)
  File "/usr/local/lib/python3.9/site-packages/rest_framework/views.py", line 480, in raise_uncaught_exception
    raise exc
  File "/usr/local/lib/python3.9/site-packages/rest_framework/views.py", line 506, in dispatch
    response = handler(request, *args, **kwargs)
  File "/usr/local/lib/python3.9/site-packages/rest_framework/generics.py", line 208, in get
    return self.retrieve(request, *args, **kwargs)
  File "/usr/src/app/doctor/views.py", line 52, in retrieve
    doctor: Doctor = self.get_object(kwargs.pop('pk'))
  File "/usr/src/app/doctor/views.py", line 45, in get_object
    return Doctor.objects.prefetch_related('specs', 'specification').get(pk=pk)
  File "/usr/local/lib/python3.9/site-packages/django/db/models/query.py", line 492, in get
    num = len(clone)
  File "/usr/local/lib/python3.9/site-packages/django/db/models/query.py", line 302, in __len__
    self._fetch_all()
  File "/usr/local/lib/python3.9/site-packages/django/db/models/query.py", line 1509, in _fetch_all
    self._prefetch_related_objects()
  File "/usr/local/lib/python3.9/site-packages/django/db/models/query.py", line 915, in _prefetch_related_objects
    prefetch_related_objects(self._result_cache, *self._prefetch_related_lookups)
  File "/usr/local/lib/python3.9/site-packages/django/db/models/query.py", line 1935, in prefetch_related_objects
    raise AttributeError(
AttributeError: Cannot find 'specification' on Doctor object, 'specification' is an invalid parameter to prefetch_related()
[2022-07-16 08:14:45,470] ERROR [django.request.log_response:241] Internal Server Error: /doctor/3/
Traceback (most recent call last):
  File "/usr/local/lib/python3.9/site-packages/django/core/handlers/exception.py", line 55, in inner
    response = get_response(request)
  File "/usr/local/lib/python3.9/site-packages/django/core/handlers/base.py", line 197, in _get_response
    response = wrapped_callback(request, *callback_args, **callback_kwargs)
  File "/usr/local/lib/python3.9/site-packages/django/views/decorators/csrf.py", line 54, in wrapped_view
    return view_func(*args, **kwargs)
  File "/usr/local/lib/python3.9/site-packages/django/views/generic/base.py", line 84, in view
    return self.dispatch(request, *args, **kwargs)
  File "/usr/local/lib/python3.9/site-packages/rest_framework/views.py", line 509, in dispatch
    response = self.handle_exception(exc)
  File "/usr/local/lib/python3.9/site-packages/rest_framework/views.py", line 469, in handle_exception
    self.raise_uncaught_exception(exc)
  File "/usr/local/lib/python3.9/site-packages/rest_framework/views.py", line 480, in raise_uncaught_exception
    raise exc
  File "/usr/local/lib/python3.9/site-packages/rest_framework/views.py", line 506, in dispatch
    response = handler(request, *args, **kwargs)
  File "/usr/local/lib/python3.9/site-packages/rest_framework/generics.py", line 208, in get
    return self.retrieve(request, *args, **kwargs)
  File "/usr/src/app/doctor/views.py", line 60, in retrieve
    serializer: DoctorSerializer = DoctorSerializer(instance = doctor)
NameError: name 'doctor' is not defined
[2022-07-16 08:18:26,358] ERROR [django.request.log_response:241] Internal Server Error: /doctor/3/
Traceback (most recent call last):
  File "/usr/local/lib/python3.9/site-packages/django/core/handlers/exception.py", line 55, in inner
    response = get_response(request)
  File "/usr/local/lib/python3.9/site-packages/django/core/handlers/base.py", line 197, in _get_response
    response = wrapped_callback(request, *callback_args, **callback_kwargs)
  File "/usr/local/lib/python3.9/site-packages/django/views/decorators/csrf.py", line 54, in wrapped_view
    return view_func(*args, **kwargs)
  File "/usr/local/lib/python3.9/site-packages/django/views/generic/base.py", line 84, in view
    return self.dispatch(request, *args, **kwargs)
  File "/usr/local/lib/python3.9/site-packages/rest_framework/views.py", line 509, in dispatch
    response = self.handle_exception(exc)
  File "/usr/local/lib/python3.9/site-packages/rest_framework/views.py", line 469, in handle_exception
    self.raise_uncaught_exception(exc)
  File "/usr/local/lib/python3.9/site-packages/rest_framework/views.py", line 480, in raise_uncaught_exception
    raise exc
  File "/usr/local/lib/python3.9/site-packages/rest_framework/views.py", line 506, in dispatch
    response = handler(request, *args, **kwargs)
  File "/usr/local/lib/python3.9/site-packages/rest_framework/generics.py", line 208, in get
    return self.retrieve(request, *args, **kwargs)
  File "/usr/src/app/doctor/views.py", line 61, in retrieve
    print(spec.doctor.name)
AttributeError: 'Doctor' object has no attribute 'name'
[2022-07-16 08:42:34,796] ERROR [django.request.log_response:241] Internal Server Error: /doctor/1/
Traceback (most recent call last):
  File "/usr/local/lib/python3.9/site-packages/django/core/handlers/exception.py", line 55, in inner
    response = get_response(request)
  File "/usr/local/lib/python3.9/site-packages/django/core/handlers/base.py", line 197, in _get_response
    response = wrapped_callback(request, *callback_args, **callback_kwargs)
  File "/usr/local/lib/python3.9/site-packages/django/views/decorators/csrf.py", line 54, in wrapped_view
    return view_func(*args, **kwargs)
  File "/usr/local/lib/python3.9/site-packages/django/views/generic/base.py", line 84, in view
    return self.dispatch(request, *args, **kwargs)
  File "/usr/local/lib/python3.9/site-packages/rest_framework/views.py", line 509, in dispatch
    response = self.handle_exception(exc)
  File "/usr/local/lib/python3.9/site-packages/rest_framework/views.py", line 469, in handle_exception
    self.raise_uncaught_exception(exc)
  File "/usr/local/lib/python3.9/site-packages/rest_framework/views.py", line 480, in raise_uncaught_exception
    raise exc
  File "/usr/local/lib/python3.9/site-packages/rest_framework/views.py", line 506, in dispatch
    response = handler(request, *args, **kwargs)
  File "/usr/local/lib/python3.9/site-packages/rest_framework/generics.py", line 208, in get
    return self.retrieve(request, *args, **kwargs)
  File "/usr/src/app/doctor/views.py", line 70, in retrieve
    .get(pk = kwargs.pop('pk'))
KeyError: 'pk'
[2022-07-16 08:42:34,810] ERROR [django.server.log_message:187] "GET /doctor/1/ HTTP/1.1" 500 94301
[2022-07-16 08:50:49,587] ERROR [django.request.log_response:241] Internal Server Error: /doctor/1/
Traceback (most recent call last):
  File "/usr/local/lib/python3.9/site-packages/django/core/handlers/exception.py", line 55, in inner
    response = get_response(request)
  File "/usr/local/lib/python3.9/site-packages/django/core/handlers/base.py", line 197, in _get_response
    response = wrapped_callback(request, *callback_args, **callback_kwargs)
  File "/usr/local/lib/python3.9/site-packages/django/views/decorators/csrf.py", line 54, in wrapped_view
    return view_func(*args, **kwargs)
  File "/usr/local/lib/python3.9/site-packages/django/views/generic/base.py", line 84, in view
    return self.dispatch(request, *args, **kwargs)
  File "/usr/local/lib/python3.9/site-packages/rest_framework/views.py", line 509, in dispatch
    response = self.handle_exception(exc)
  File "/usr/local/lib/python3.9/site-packages/rest_framework/views.py", line 469, in handle_exception
    self.raise_uncaught_exception(exc)
  File "/usr/local/lib/python3.9/site-packages/rest_framework/views.py", line 480, in raise_uncaught_exception
    raise exc
  File "/usr/local/lib/python3.9/site-packages/rest_framework/views.py", line 506, in dispatch
    response = handler(request, *args, **kwargs)
  File "/usr/local/lib/python3.9/site-packages/rest_framework/generics.py", line 208, in get
    return self.retrieve(request, *args, **kwargs)
  File "/usr/src/app/doctor/views.py", line 76, in retrieve
    print(doctor.prefetch_related_objects())
AttributeError: 'Doctor' object has no attribute 'prefetch_related_objects'
[2022-07-16 08:50:49,612] ERROR [django.server.log_message:187] "GET /doctor/1/ HTTP/1.1" 500 94891
[2022-07-16 08:51:24,347] ERROR [django.request.log_response:241] Internal Server Error: /doctor/1/
Traceback (most recent call last):
  File "/usr/local/lib/python3.9/site-packages/django/core/handlers/exception.py", line 55, in inner
    response = get_response(request)
  File "/usr/local/lib/python3.9/site-packages/django/core/handlers/base.py", line 197, in _get_response
    response = wrapped_callback(request, *callback_args, **callback_kwargs)
  File "/usr/local/lib/python3.9/site-packages/django/views/decorators/csrf.py", line 54, in wrapped_view
    return view_func(*args, **kwargs)
  File "/usr/local/lib/python3.9/site-packages/django/views/generic/base.py", line 84, in view
    return self.dispatch(request, *args, **kwargs)
  File "/usr/local/lib/python3.9/site-packages/rest_framework/views.py", line 509, in dispatch
    response = self.handle_exception(exc)
  File "/usr/local/lib/python3.9/site-packages/rest_framework/views.py", line 469, in handle_exception
    self.raise_uncaught_exception(exc)
  File "/usr/local/lib/python3.9/site-packages/rest_framework/views.py", line 480, in raise_uncaught_exception
    raise exc
  File "/usr/local/lib/python3.9/site-packages/rest_framework/views.py", line 506, in dispatch
    response = handler(request, *args, **kwargs)
  File "/usr/local/lib/python3.9/site-packages/rest_framework/generics.py", line 208, in get
    return self.retrieve(request, *args, **kwargs)
  File "/usr/src/app/doctor/views.py", line 79, in retrieve
    for spec in doctor.specs:
TypeError: 'RelatedManager' object is not iterable
[2022-07-16 08:51:24,379] ERROR [django.server.log_message:187] "GET /doctor/1/ HTTP/1.1" 500 94615
[2022-07-16 09:09:52,611] ERROR [django.request.log_response:241] Internal Server Error: /doctor/1/
Traceback (most recent call last):
  File "/usr/local/lib/python3.9/site-packages/django/core/handlers/exception.py", line 55, in inner
    response = get_response(request)
  File "/usr/local/lib/python3.9/site-packages/django/core/handlers/base.py", line 197, in _get_response
    response = wrapped_callback(request, *callback_args, **callback_kwargs)
  File "/usr/local/lib/python3.9/site-packages/django/views/decorators/csrf.py", line 54, in wrapped_view
    return view_func(*args, **kwargs)
  File "/usr/local/lib/python3.9/site-packages/django/views/generic/base.py", line 84, in view
    return self.dispatch(request, *args, **kwargs)
  File "/usr/local/lib/python3.9/site-packages/rest_framework/views.py", line 509, in dispatch
    response = self.handle_exception(exc)
  File "/usr/local/lib/python3.9/site-packages/rest_framework/views.py", line 469, in handle_exception
    self.raise_uncaught_exception(exc)
  File "/usr/local/lib/python3.9/site-packages/rest_framework/views.py", line 480, in raise_uncaught_exception
    raise exc
  File "/usr/local/lib/python3.9/site-packages/rest_framework/views.py", line 506, in dispatch
    response = handler(request, *args, **kwargs)
  File "/usr/local/lib/python3.9/site-packages/rest_framework/generics.py", line 208, in get
    return self.retrieve(request, *args, **kwargs)
  File "/usr/src/app/doctor/views.py", line 79, in retrieve
    for spec in doctor.specs:
TypeError: 'RelatedManager' object is not iterable
[2022-07-16 09:09:52,622] ERROR [django.server.log_message:187] "GET /doctor/1/ HTTP/1.1" 500 94764
[2022-07-16 09:14:52,104] ERROR [django.request.log_response:241] Internal Server Error: /doctor/1/
Traceback (most recent call last):
  File "/usr/local/lib/python3.9/site-packages/django/core/handlers/exception.py", line 55, in inner
    response = get_response(request)
  File "/usr/local/lib/python3.9/site-packages/django/core/handlers/base.py", line 220, in _get_response
    response = response.render()
  File "/usr/local/lib/python3.9/site-packages/django/template/response.py", line 114, in render
    self.content = self.rendered_content
  File "/usr/local/lib/python3.9/site-packages/rest_framework/response.py", line 70, in rendered_content
    ret = renderer.render(self.data, accepted_media_type, context)
  File "/usr/local/lib/python3.9/site-packages/rest_framework/renderers.py", line 100, in render
    ret = json.dumps(
  File "/usr/local/lib/python3.9/site-packages/rest_framework/utils/json.py", line 25, in dumps
    return json.dumps(*args, **kwargs)
  File "/usr/local/lib/python3.9/json/__init__.py", line 234, in dumps
    return cls(
  File "/usr/local/lib/python3.9/json/encoder.py", line 199, in encode
    chunks = self.iterencode(o, _one_shot=True)
  File "/usr/local/lib/python3.9/json/encoder.py", line 257, in iterencode
    return _iterencode(o, 0)
  File "/usr/local/lib/python3.9/site-packages/rest_framework/utils/encoders.py", line 67, in default
    return super().default(obj)
  File "/usr/local/lib/python3.9/json/encoder.py", line 179, in default
    raise TypeError(f'Object of type {o.__class__.__name__} '
TypeError: Object of type Specification is not JSON serializable
[2022-07-16 09:14:52,112] ERROR [django.server.log_message:187] "GET /doctor/1/ HTTP/1.1" 500 104719
[2022-07-16 09:23:52,819] WARNING [django.security.csrf.log_response:241] Forbidden (CSRF cookie not set.): /admin/doctor/1/
[2022-07-16 09:23:52,822] WARNING [django.server.log_message:187] "PUT /admin/doctor/1/ HTTP/1.1" 403 2870
[2022-07-16 09:24:53,784] WARNING [django.security.csrf.log_response:241] Forbidden (CSRF cookie not set.): /admin/doctor/1/
[2022-07-16 09:24:53,787] WARNING [django.server.log_message:187] "PUT /admin/doctor/1/ HTTP/1.1" 403 2870
[2022-07-16 09:25:10,440] WARNING [django.security.csrf.log_response:241] Forbidden (CSRF cookie not set.): /admin/doctor/1/
[2022-07-16 09:25:10,442] WARNING [django.server.log_message:187] "PUT /admin/doctor/1/ HTTP/1.1" 403 2870
