[2022-07-31 03:12:32,456] WARNING [django.request.log_response:241] Not Found: /user/patients/
[2022-07-31 03:15:14,511] WARNING [django.request.log_response:241] Unauthorized: /user/patients/
[2022-07-31 03:15:14,783] WARNING [django.request.log_response:241] Not Found: /favicon.ico
[2022-07-31 03:26:48,935] WARNING [django.request.log_response:241] Bad Request: /user/patients/
[2022-07-31 03:27:40,753] WARNING [django.request.log_response:241] Bad Request: /user/patients/
[2022-07-31 03:27:58,699] WARNING [django.request.log_response:241] Bad Request: /user/me/password/
[2022-07-31 03:28:06,391] WARNING [django.request.log_response:241] Bad Request: /user/me/password/
[2022-07-31 06:58:20,777] WARNING [django.request.log_response:241] Unauthorized: /user/patients/
[2022-07-31 06:58:51,005] WARNING [django.request.log_response:241] Forbidden: /login/
[2022-07-31 07:23:59,881] ERROR [django.request.log_response:241] Internal Server Error: /patients/1
[2022-07-31 07:25:34,004] ERROR [shared.exception_handler.__handle_http404:111] No Patient matches the given query.
[2022-07-31 07:25:34,008] WARNING [django.request.log_response:241] Not Found: /patients/2
[2022-07-31 07:38:18,393] ERROR [django.request.log_response:241] Internal Server Error: /patients/1
Traceback (most recent call last):
  File "/usr/local/lib/python3.9/site-packages/django/core/handlers/exception.py", line 55, in inner
    response = get_response(request)
  File "/usr/local/lib/python3.9/site-packages/django/core/handlers/base.py", line 220, in _get_response
    response = response.render()
  File "/usr/local/lib/python3.9/site-packages/django/template/response.py", line 114, in render
    self.content = self.rendered_content
  File "/usr/local/lib/python3.9/site-packages/rest_framework/response.py", line 70, in rendered_content
    ret = renderer.render(self.data, accepted_media_type, context)
  File "/usr/local/lib/python3.9/site-packages/rest_framework/renderers.py", line 100, in render
    ret = json.dumps(
  File "/usr/local/lib/python3.9/site-packages/rest_framework/utils/json.py", line 25, in dumps
    return json.dumps(*args, **kwargs)
  File "/usr/local/lib/python3.9/json/__init__.py", line 234, in dumps
    return cls(
  File "/usr/local/lib/python3.9/json/encoder.py", line 199, in encode
    chunks = self.iterencode(o, _one_shot=True)
  File "/usr/local/lib/python3.9/json/encoder.py", line 257, in iterencode
    return _iterencode(o, 0)
  File "/usr/local/lib/python3.9/site-packages/rest_framework/utils/encoders.py", line 67, in default
    return super().default(obj)
  File "/usr/local/lib/python3.9/json/encoder.py", line 179, in default
    raise TypeError(f'Object of type {o.__class__.__name__} '
TypeError: Object of type ModelState is not JSON serializable
[2022-07-31 07:51:21,704] ERROR [django.request.log_response:241] Internal Server Error: /patients/1
[2022-07-31 07:51:45,115] WARNING [django.request.log_response:241] Bad Request: /patients/1
[2022-07-31 07:56:29,043] ERROR [shared.exception_handler.__handle_http404:111] No Patient matches the given query.
[2022-07-31 07:56:29,045] WARNING [django.request.log_response:241] Not Found: /user/patients/1
[2022-07-31 08:04:12,291] ERROR [shared.exception_handler.__handle_http404:111] No Patient matches the given query.
[2022-07-31 08:04:12,294] WARNING [django.request.log_response:241] Not Found: /user/patients/1
[2022-07-31 08:04:30,492] ERROR [django.request.log_response:241] Internal Server Error: /user/patients/2
[2022-07-31 08:05:45,247] ERROR [django.request.log_response:241] Internal Server Error: /user/patients/2
[2022-07-31 08:09:39,759] ERROR [django.request.log_response:241] Internal Server Error: /user/patients/2
